INFO:django.utils.autoreload:/home/work/learning/tasks/book_app2/books/urls.py changed, reloading.
WARNING:django.request:Not Found: /
INFO:django.utils.autoreload:/home/work/learning/tasks/book_app2/books/urls.py changed, reloading.
INFO:django.utils.autoreload:/home/work/learning/tasks/book_app2/books/views/book_api.py changed, reloading.
INFO:django.utils.autoreload:/home/work/learning/tasks/book_app2/books/views/book_api.py changed, reloading.
INFO:django.utils.autoreload:/home/work/learning/tasks/book_app2/books/views/book_api.py changed, reloading.
INFO:django.utils.autoreload:/home/work/learning/tasks/book_app2/books/views/book_api.py changed, reloading.
INFO:django.utils.autoreload:/home/work/learning/tasks/book_app2/books/views/book_api.py changed, reloading.
INFO:django.utils.autoreload:/home/work/learning/tasks/book_app2/books/views/book_api.py changed, reloading.
INFO:django.utils.autoreload:/home/work/learning/tasks/book_app2/books/views/book_api.py changed, reloading.
WARNING:django.request:Not Found: /
ERROR:django.request:Internal Server Error: /api/v1/books/1/
Traceback (most recent call last):
  File "/home/work/learning/tasks/book_app2/.venv/lib/python3.12/site-packages/django/core/handlers/exception.py", line 55, in inner
    response = get_response(request)
               ^^^^^^^^^^^^^^^^^^^^^
  File "/home/work/learning/tasks/book_app2/.venv/lib/python3.12/site-packages/django/core/handlers/base.py", line 197, in _get_response
    response = wrapped_callback(request, *callback_args, **callback_kwargs)
               ^^^^^^^^^^^^^^^^^^^^^^^^^^^^^^^^^^^^^^^^^^^^^^^^^^^^^^^^^^^^
  File "/home/work/learning/tasks/book_app2/.venv/lib/python3.12/site-packages/django/views/decorators/csrf.py", line 65, in _view_wrapper
    return view_func(request, *args, **kwargs)
           ^^^^^^^^^^^^^^^^^^^^^^^^^^^^^^^^^^^
  File "/home/work/learning/tasks/book_app2/.venv/lib/python3.12/site-packages/django/views/generic/base.py", line 104, in view
    return self.dispatch(request, *args, **kwargs)
           ^^^^^^^^^^^^^^^^^^^^^^^^^^^^^^^^^^^^^^^
  File "/home/work/learning/tasks/book_app2/.venv/lib/python3.12/site-packages/rest_framework/views.py", line 509, in dispatch
    response = self.handle_exception(exc)
               ^^^^^^^^^^^^^^^^^^^^^^^^^^
  File "/home/work/learning/tasks/book_app2/.venv/lib/python3.12/site-packages/rest_framework/views.py", line 469, in handle_exception
    self.raise_uncaught_exception(exc)
  File "/home/work/learning/tasks/book_app2/.venv/lib/python3.12/site-packages/rest_framework/views.py", line 480, in raise_uncaught_exception
    raise exc
  File "/home/work/learning/tasks/book_app2/.venv/lib/python3.12/site-packages/rest_framework/views.py", line 506, in dispatch
    response = handler(request, *args, **kwargs)
               ^^^^^^^^^^^^^^^^^^^^^^^^^^^^^^^^^
  File "/home/work/learning/tasks/book_app2/.venv/lib/python3.12/site-packages/rest_framework/decorators.py", line 50, in handler
    return func(*args, **kwargs)
           ^^^^^^^^^^^^^^^^^^^^^
TypeError: book_detail() got an unexpected keyword argument 'id'
INFO:django.utils.autoreload:/home/work/learning/tasks/book_app2/books/views/book_api.py changed, reloading.
ERROR:django.request:Internal Server Error: /api/v1/books/1/
Traceback (most recent call last):
  File "/home/work/learning/tasks/book_app2/.venv/lib/python3.12/site-packages/django/core/handlers/exception.py", line 55, in inner
    response = get_response(request)
               ^^^^^^^^^^^^^^^^^^^^^
  File "/home/work/learning/tasks/book_app2/.venv/lib/python3.12/site-packages/django/core/handlers/base.py", line 197, in _get_response
    response = wrapped_callback(request, *callback_args, **callback_kwargs)
               ^^^^^^^^^^^^^^^^^^^^^^^^^^^^^^^^^^^^^^^^^^^^^^^^^^^^^^^^^^^^
  File "/home/work/learning/tasks/book_app2/.venv/lib/python3.12/site-packages/django/views/decorators/csrf.py", line 65, in _view_wrapper
    return view_func(request, *args, **kwargs)
           ^^^^^^^^^^^^^^^^^^^^^^^^^^^^^^^^^^^
  File "/home/work/learning/tasks/book_app2/.venv/lib/python3.12/site-packages/django/views/generic/base.py", line 104, in view
    return self.dispatch(request, *args, **kwargs)
           ^^^^^^^^^^^^^^^^^^^^^^^^^^^^^^^^^^^^^^^
  File "/home/work/learning/tasks/book_app2/.venv/lib/python3.12/site-packages/rest_framework/views.py", line 509, in dispatch
    response = self.handle_exception(exc)
               ^^^^^^^^^^^^^^^^^^^^^^^^^^
  File "/home/work/learning/tasks/book_app2/.venv/lib/python3.12/site-packages/rest_framework/views.py", line 469, in handle_exception
    self.raise_uncaught_exception(exc)
  File "/home/work/learning/tasks/book_app2/.venv/lib/python3.12/site-packages/rest_framework/views.py", line 480, in raise_uncaught_exception
    raise exc
  File "/home/work/learning/tasks/book_app2/.venv/lib/python3.12/site-packages/rest_framework/views.py", line 506, in dispatch
    response = handler(request, *args, **kwargs)
               ^^^^^^^^^^^^^^^^^^^^^^^^^^^^^^^^^
  File "/home/work/learning/tasks/book_app2/.venv/lib/python3.12/site-packages/rest_framework/decorators.py", line 50, in handler
    return func(*args, **kwargs)
           ^^^^^^^^^^^^^^^^^^^^^
TypeError: book_detail() got an unexpected keyword argument 'id'
INFO:django.utils.autoreload:/home/work/learning/tasks/book_app2/books/urls.py changed, reloading.
ERROR:books.helpers.logging_helper:BookDetailView get :: exception :: Book matching query does not exist.
ERROR:django.request:Internal Server Error: /api/v1/books/1/
Traceback (most recent call last):
  File "/home/work/learning/tasks/book_app2/.venv/lib/python3.12/site-packages/django/core/handlers/exception.py", line 55, in inner
    response = get_response(request)
               ^^^^^^^^^^^^^^^^^^^^^
  File "/home/work/learning/tasks/book_app2/.venv/lib/python3.12/site-packages/django/core/handlers/base.py", line 220, in _get_response
    response = response.render()
               ^^^^^^^^^^^^^^^^^
  File "/home/work/learning/tasks/book_app2/.venv/lib/python3.12/site-packages/django/template/response.py", line 114, in render
    self.content = self.rendered_content
                   ^^^^^^^^^^^^^^^^^^^^^
  File "/home/work/learning/tasks/book_app2/.venv/lib/python3.12/site-packages/rest_framework/response.py", line 74, in rendered_content
    ret = renderer.render(self.data, accepted_media_type, context)
          ^^^^^^^^^^^^^^^^^^^^^^^^^^^^^^^^^^^^^^^^^^^^^^^^^^^^^^^^
  File "/home/work/learning/tasks/book_app2/.venv/lib/python3.12/site-packages/rest_framework/renderers.py", line 726, in render
    context = self.get_context(data, accepted_media_type, renderer_context)
              ^^^^^^^^^^^^^^^^^^^^^^^^^^^^^^^^^^^^^^^^^^^^^^^^^^^^^^^^^^^^^
  File "/home/work/learning/tasks/book_app2/.venv/lib/python3.12/site-packages/rest_framework/renderers.py", line 682, in get_context
    'content': self.get_content(renderer, data, accepted_media_type, renderer_context),
               ^^^^^^^^^^^^^^^^^^^^^^^^^^^^^^^^^^^^^^^^^^^^^^^^^^^^^^^^^^^^^^^^^^^^^^^
  File "/home/work/learning/tasks/book_app2/.venv/lib/python3.12/site-packages/rest_framework/renderers.py", line 412, in get_content
    content = renderer.render(data, accepted_media_type, renderer_context)
              ^^^^^^^^^^^^^^^^^^^^^^^^^^^^^^^^^^^^^^^^^^^^^^^^^^^^^^^^^^^^
  File "/home/work/learning/tasks/book_app2/.venv/lib/python3.12/site-packages/rest_framework/renderers.py", line 99, in render
    ret = json.dumps(
          ^^^^^^^^^^^
  File "/home/work/learning/tasks/book_app2/.venv/lib/python3.12/site-packages/rest_framework/utils/json.py", line 25, in dumps
    return json.dumps(*args, **kwargs)
           ^^^^^^^^^^^^^^^^^^^^^^^^^^^
  File "/usr/lib/python3.12/json/__init__.py", line 238, in dumps
    **kw).encode(obj)
          ^^^^^^^^^^^
  File "/usr/lib/python3.12/json/encoder.py", line 202, in encode
    chunks = list(chunks)
             ^^^^^^^^^^^^
  File "/usr/lib/python3.12/json/encoder.py", line 432, in _iterencode
    yield from _iterencode_dict(o, _current_indent_level)
  File "/usr/lib/python3.12/json/encoder.py", line 406, in _iterencode_dict
    yield from chunks
  File "/usr/lib/python3.12/json/encoder.py", line 439, in _iterencode
    o = _default(o)
        ^^^^^^^^^^^
  File "/home/work/learning/tasks/book_app2/.venv/lib/python3.12/site-packages/rest_framework/utils/encoders.py", line 67, in default
    return super().default(obj)
           ^^^^^^^^^^^^^^^^^^^^
  File "/usr/lib/python3.12/json/encoder.py", line 180, in default
    raise TypeError(f'Object of type {o.__class__.__name__} '
TypeError: Object of type DoesNotExist is not JSON serializable
ERROR:books.helpers.logging_helper:BookDetailView get :: exception :: Book matching query does not exist.
ERROR:django.request:Internal Server Error: /api/v1/books/1/
Traceback (most recent call last):
  File "/home/work/learning/tasks/book_app2/.venv/lib/python3.12/site-packages/django/core/handlers/exception.py", line 55, in inner
    response = get_response(request)
               ^^^^^^^^^^^^^^^^^^^^^
  File "/home/work/learning/tasks/book_app2/.venv/lib/python3.12/site-packages/django/core/handlers/base.py", line 220, in _get_response
    response = response.render()
               ^^^^^^^^^^^^^^^^^
  File "/home/work/learning/tasks/book_app2/.venv/lib/python3.12/site-packages/django/template/response.py", line 114, in render
    self.content = self.rendered_content
                   ^^^^^^^^^^^^^^^^^^^^^
  File "/home/work/learning/tasks/book_app2/.venv/lib/python3.12/site-packages/rest_framework/response.py", line 74, in rendered_content
    ret = renderer.render(self.data, accepted_media_type, context)
          ^^^^^^^^^^^^^^^^^^^^^^^^^^^^^^^^^^^^^^^^^^^^^^^^^^^^^^^^
  File "/home/work/learning/tasks/book_app2/.venv/lib/python3.12/site-packages/rest_framework/renderers.py", line 726, in render
    context = self.get_context(data, accepted_media_type, renderer_context)
              ^^^^^^^^^^^^^^^^^^^^^^^^^^^^^^^^^^^^^^^^^^^^^^^^^^^^^^^^^^^^^
  File "/home/work/learning/tasks/book_app2/.venv/lib/python3.12/site-packages/rest_framework/renderers.py", line 682, in get_context
    'content': self.get_content(renderer, data, accepted_media_type, renderer_context),
               ^^^^^^^^^^^^^^^^^^^^^^^^^^^^^^^^^^^^^^^^^^^^^^^^^^^^^^^^^^^^^^^^^^^^^^^
  File "/home/work/learning/tasks/book_app2/.venv/lib/python3.12/site-packages/rest_framework/renderers.py", line 412, in get_content
    content = renderer.render(data, accepted_media_type, renderer_context)
              ^^^^^^^^^^^^^^^^^^^^^^^^^^^^^^^^^^^^^^^^^^^^^^^^^^^^^^^^^^^^
  File "/home/work/learning/tasks/book_app2/.venv/lib/python3.12/site-packages/rest_framework/renderers.py", line 99, in render
    ret = json.dumps(
          ^^^^^^^^^^^
  File "/home/work/learning/tasks/book_app2/.venv/lib/python3.12/site-packages/rest_framework/utils/json.py", line 25, in dumps
    return json.dumps(*args, **kwargs)
           ^^^^^^^^^^^^^^^^^^^^^^^^^^^
  File "/usr/lib/python3.12/json/__init__.py", line 238, in dumps
    **kw).encode(obj)
          ^^^^^^^^^^^
  File "/usr/lib/python3.12/json/encoder.py", line 202, in encode
    chunks = list(chunks)
             ^^^^^^^^^^^^
  File "/usr/lib/python3.12/json/encoder.py", line 432, in _iterencode
    yield from _iterencode_dict(o, _current_indent_level)
  File "/usr/lib/python3.12/json/encoder.py", line 406, in _iterencode_dict
    yield from chunks
  File "/usr/lib/python3.12/json/encoder.py", line 439, in _iterencode
    o = _default(o)
        ^^^^^^^^^^^
  File "/home/work/learning/tasks/book_app2/.venv/lib/python3.12/site-packages/rest_framework/utils/encoders.py", line 67, in default
    return super().default(obj)
           ^^^^^^^^^^^^^^^^^^^^
  File "/usr/lib/python3.12/json/encoder.py", line 180, in default
    raise TypeError(f'Object of type {o.__class__.__name__} '
TypeError: Object of type DoesNotExist is not JSON serializable
INFO:django.utils.autoreload:/home/work/learning/tasks/book_app2/books/urls.py changed, reloading.
INFO:django.utils.autoreload:/home/work/learning/tasks/book_app2/books/urls.py changed, reloading.
ERROR:books.helpers.logging_helper:BookDetailView get :: exception :: ['“1” is not a valid UUID.']
WARNING:django.request:Bad Request: /api/v1/books/1/
INFO:django.utils.autoreload:/home/work/learning/tasks/book_app2/books/views/book_api.py changed, reloading.
INFO:django.utils.autoreload:/home/work/learning/tasks/book_app2/books/serializers/book_serializer.py changed, reloading.
ERROR:books.helpers.logging_helper:BookDetailView get :: exception :: ['“1” is not a valid UUID.']
WARNING:django.request:Bad Request: /api/v1/books/1/
ERROR:books.helpers.logging_helper:BookDetailView get :: exception :: ['“1” is not a valid UUID.']
WARNING:django.request:Bad Request: /api/v1/books/1/
INFO:django.utils.autoreload:/home/work/learning/tasks/book_app2/books/services/book_service.py changed, reloading.
WARNING:django.request:Not Found: /favicon.ico
WARNING:django.request:Not Found: /favicon.ico
WARNING:django.request:Not Found: /favicon.ico
WARNING:django.request:Not Found: /favicon.ico
WARNING:django.request:Not Found: /favicon.ico
WARNING:django.request:Not Found: /favicon.ico
WARNING:django.request:Not Found: /favicon.ico
WARNING:django.request:Not Found: /favicon.ico
ERROR:books.helpers.logging_helper:BookView get :: exception::  can only concatenate str (not "ImageFieldFile") to str
ERROR:django.request:Internal Server Error: /api/v1/books/
Traceback (most recent call last):
  File "/home/work/learning/tasks/book_app2/books/views/book_api.py", line 13, in book_list
    books = book_service.get_all_book()
            ^^^^^^^^^^^^^^^^^^^^^^^^^^^
  File "/home/work/learning/tasks/book_app2/books/services/book_service.py", line 9, in get_all_book
    books = ['localhost:8000/'+ book.image for book in books]
             ~~~~~~~~~~~~~~~~~^~~~~~~~~~~~
TypeError: can only concatenate str (not "ImageFieldFile") to str

During handling of the above exception, another exception occurred:

Traceback (most recent call last):
  File "/home/work/learning/tasks/book_app2/.venv/lib/python3.12/site-packages/django/core/handlers/exception.py", line 55, in inner
    response = get_response(request)
               ^^^^^^^^^^^^^^^^^^^^^
  File "/home/work/learning/tasks/book_app2/.venv/lib/python3.12/site-packages/django/core/handlers/base.py", line 197, in _get_response
    response = wrapped_callback(request, *callback_args, **callback_kwargs)
               ^^^^^^^^^^^^^^^^^^^^^^^^^^^^^^^^^^^^^^^^^^^^^^^^^^^^^^^^^^^^
  File "/home/work/learning/tasks/book_app2/.venv/lib/python3.12/site-packages/django/views/decorators/csrf.py", line 65, in _view_wrapper
    return view_func(request, *args, **kwargs)
           ^^^^^^^^^^^^^^^^^^^^^^^^^^^^^^^^^^^
  File "/home/work/learning/tasks/book_app2/.venv/lib/python3.12/site-packages/django/views/generic/base.py", line 104, in view
    return self.dispatch(request, *args, **kwargs)
           ^^^^^^^^^^^^^^^^^^^^^^^^^^^^^^^^^^^^^^^
  File "/home/work/learning/tasks/book_app2/.venv/lib/python3.12/site-packages/rest_framework/views.py", line 509, in dispatch
    response = self.handle_exception(exc)
               ^^^^^^^^^^^^^^^^^^^^^^^^^^
  File "/home/work/learning/tasks/book_app2/.venv/lib/python3.12/site-packages/rest_framework/views.py", line 469, in handle_exception
    self.raise_uncaught_exception(exc)
  File "/home/work/learning/tasks/book_app2/.venv/lib/python3.12/site-packages/rest_framework/views.py", line 480, in raise_uncaught_exception
    raise exc
  File "/home/work/learning/tasks/book_app2/.venv/lib/python3.12/site-packages/rest_framework/views.py", line 506, in dispatch
    response = handler(request, *args, **kwargs)
               ^^^^^^^^^^^^^^^^^^^^^^^^^^^^^^^^^
  File "/home/work/learning/tasks/book_app2/.venv/lib/python3.12/site-packages/rest_framework/decorators.py", line 50, in handler
    return func(*args, **kwargs)
           ^^^^^^^^^^^^^^^^^^^^^
  File "/home/work/learning/tasks/book_app2/books/views/book_api.py", line 19, in book_list
    return response_builder.get_200_success_response()
           ^^^^^^^^^^^^^^^^^^^^^^^^^^^^^^^^^^^^^^^^^^^
TypeError: ResponseBuilder.get_200_success_response() missing 1 required positional argument: 'message'
INFO:django.utils.autoreload:/home/work/learning/tasks/book_app2/books/views/book_api.py changed, reloading.
ERROR:books.helpers.logging_helper:BookView get :: exception::  can only concatenate str (not "ImageFieldFile") to str
ERROR:django.request:Internal Server Error: /api/v1/books/
Traceback (most recent call last):
  File "/home/work/learning/tasks/book_app2/.venv/lib/python3.12/site-packages/django/core/handlers/exception.py", line 55, in inner
    response = get_response(request)
               ^^^^^^^^^^^^^^^^^^^^^
  File "/home/work/learning/tasks/book_app2/.venv/lib/python3.12/site-packages/django/core/handlers/base.py", line 220, in _get_response
    response = response.render()
               ^^^^^^^^^^^^^^^^^
  File "/home/work/learning/tasks/book_app2/.venv/lib/python3.12/site-packages/django/template/response.py", line 114, in render
    self.content = self.rendered_content
                   ^^^^^^^^^^^^^^^^^^^^^
  File "/home/work/learning/tasks/book_app2/.venv/lib/python3.12/site-packages/rest_framework/response.py", line 74, in rendered_content
    ret = renderer.render(self.data, accepted_media_type, context)
          ^^^^^^^^^^^^^^^^^^^^^^^^^^^^^^^^^^^^^^^^^^^^^^^^^^^^^^^^
  File "/home/work/learning/tasks/book_app2/.venv/lib/python3.12/site-packages/rest_framework/renderers.py", line 726, in render
    context = self.get_context(data, accepted_media_type, renderer_context)
              ^^^^^^^^^^^^^^^^^^^^^^^^^^^^^^^^^^^^^^^^^^^^^^^^^^^^^^^^^^^^^
  File "/home/work/learning/tasks/book_app2/.venv/lib/python3.12/site-packages/rest_framework/renderers.py", line 682, in get_context
    'content': self.get_content(renderer, data, accepted_media_type, renderer_context),
               ^^^^^^^^^^^^^^^^^^^^^^^^^^^^^^^^^^^^^^^^^^^^^^^^^^^^^^^^^^^^^^^^^^^^^^^
  File "/home/work/learning/tasks/book_app2/.venv/lib/python3.12/site-packages/rest_framework/renderers.py", line 412, in get_content
    content = renderer.render(data, accepted_media_type, renderer_context)
              ^^^^^^^^^^^^^^^^^^^^^^^^^^^^^^^^^^^^^^^^^^^^^^^^^^^^^^^^^^^^
  File "/home/work/learning/tasks/book_app2/.venv/lib/python3.12/site-packages/rest_framework/renderers.py", line 99, in render
    ret = json.dumps(
          ^^^^^^^^^^^
  File "/home/work/learning/tasks/book_app2/.venv/lib/python3.12/site-packages/rest_framework/utils/json.py", line 25, in dumps
    return json.dumps(*args, **kwargs)
           ^^^^^^^^^^^^^^^^^^^^^^^^^^^
  File "/usr/lib/python3.12/json/__init__.py", line 238, in dumps
    **kw).encode(obj)
          ^^^^^^^^^^^
  File "/usr/lib/python3.12/json/encoder.py", line 202, in encode
    chunks = list(chunks)
             ^^^^^^^^^^^^
  File "/usr/lib/python3.12/json/encoder.py", line 432, in _iterencode
    yield from _iterencode_dict(o, _current_indent_level)
  File "/usr/lib/python3.12/json/encoder.py", line 406, in _iterencode_dict
    yield from chunks
  File "/usr/lib/python3.12/json/encoder.py", line 439, in _iterencode
    o = _default(o)
        ^^^^^^^^^^^
  File "/home/work/learning/tasks/book_app2/.venv/lib/python3.12/site-packages/rest_framework/utils/encoders.py", line 67, in default
    return super().default(obj)
           ^^^^^^^^^^^^^^^^^^^^
  File "/usr/lib/python3.12/json/encoder.py", line 180, in default
    raise TypeError(f'Object of type {o.__class__.__name__} '
TypeError: Object of type TypeError is not JSON serializable
INFO:django.utils.autoreload:/home/work/learning/tasks/book_app2/books/views/book_api.py changed, reloading.
INFO:django.utils.autoreload:/home/work/learning/tasks/book_app2/books/views/book_api.py changed, reloading.
ERROR:books.helpers.logging_helper:BookView get :: exception::  can only concatenate str (not "ImageFieldFile") to str
ERROR:django.request:Internal Server Error: /api/v1/books/
Traceback (most recent call last):
  File "/home/work/learning/tasks/book_app2/.venv/lib/python3.12/site-packages/django/core/handlers/exception.py", line 55, in inner
    response = get_response(request)
               ^^^^^^^^^^^^^^^^^^^^^
  File "/home/work/learning/tasks/book_app2/.venv/lib/python3.12/site-packages/django/core/handlers/base.py", line 220, in _get_response
    response = response.render()
               ^^^^^^^^^^^^^^^^^
  File "/home/work/learning/tasks/book_app2/.venv/lib/python3.12/site-packages/django/template/response.py", line 114, in render
    self.content = self.rendered_content
                   ^^^^^^^^^^^^^^^^^^^^^
  File "/home/work/learning/tasks/book_app2/.venv/lib/python3.12/site-packages/rest_framework/response.py", line 74, in rendered_content
    ret = renderer.render(self.data, accepted_media_type, context)
          ^^^^^^^^^^^^^^^^^^^^^^^^^^^^^^^^^^^^^^^^^^^^^^^^^^^^^^^^
  File "/home/work/learning/tasks/book_app2/.venv/lib/python3.12/site-packages/rest_framework/renderers.py", line 726, in render
    context = self.get_context(data, accepted_media_type, renderer_context)
              ^^^^^^^^^^^^^^^^^^^^^^^^^^^^^^^^^^^^^^^^^^^^^^^^^^^^^^^^^^^^^
  File "/home/work/learning/tasks/book_app2/.venv/lib/python3.12/site-packages/rest_framework/renderers.py", line 682, in get_context
    'content': self.get_content(renderer, data, accepted_media_type, renderer_context),
               ^^^^^^^^^^^^^^^^^^^^^^^^^^^^^^^^^^^^^^^^^^^^^^^^^^^^^^^^^^^^^^^^^^^^^^^
  File "/home/work/learning/tasks/book_app2/.venv/lib/python3.12/site-packages/rest_framework/renderers.py", line 412, in get_content
    content = renderer.render(data, accepted_media_type, renderer_context)
              ^^^^^^^^^^^^^^^^^^^^^^^^^^^^^^^^^^^^^^^^^^^^^^^^^^^^^^^^^^^^
  File "/home/work/learning/tasks/book_app2/.venv/lib/python3.12/site-packages/rest_framework/renderers.py", line 99, in render
    ret = json.dumps(
          ^^^^^^^^^^^
  File "/home/work/learning/tasks/book_app2/.venv/lib/python3.12/site-packages/rest_framework/utils/json.py", line 25, in dumps
    return json.dumps(*args, **kwargs)
           ^^^^^^^^^^^^^^^^^^^^^^^^^^^
  File "/usr/lib/python3.12/json/__init__.py", line 238, in dumps
    **kw).encode(obj)
          ^^^^^^^^^^^
  File "/usr/lib/python3.12/json/encoder.py", line 202, in encode
    chunks = list(chunks)
             ^^^^^^^^^^^^
  File "/usr/lib/python3.12/json/encoder.py", line 432, in _iterencode
    yield from _iterencode_dict(o, _current_indent_level)
  File "/usr/lib/python3.12/json/encoder.py", line 406, in _iterencode_dict
    yield from chunks
  File "/usr/lib/python3.12/json/encoder.py", line 440, in _iterencode
    yield from _iterencode(o, _current_indent_level)
  File "/usr/lib/python3.12/json/encoder.py", line 430, in _iterencode
    yield from _iterencode_list(o, _current_indent_level)
  File "/usr/lib/python3.12/json/encoder.py", line 326, in _iterencode_list
    yield from chunks
  File "/usr/lib/python3.12/json/encoder.py", line 439, in _iterencode
    o = _default(o)
        ^^^^^^^^^^^
  File "/home/work/learning/tasks/book_app2/.venv/lib/python3.12/site-packages/rest_framework/utils/encoders.py", line 67, in default
    return super().default(obj)
           ^^^^^^^^^^^^^^^^^^^^
  File "/usr/lib/python3.12/json/encoder.py", line 180, in default
    raise TypeError(f'Object of type {o.__class__.__name__} '
TypeError: Object of type TypeError is not JSON serializable
INFO:django.utils.autoreload:/home/work/learning/tasks/book_app2/books/views/book_api.py changed, reloading.
ERROR:books.helpers.logging_helper:BookView get :: exception::  can only concatenate str (not "ImageFieldFile") to str
ERROR:django.request:Internal Server Error: /api/v1/books/
Traceback (most recent call last):
  File "/home/work/learning/tasks/book_app2/.venv/lib/python3.12/site-packages/django/core/handlers/exception.py", line 55, in inner
    response = get_response(request)
               ^^^^^^^^^^^^^^^^^^^^^
  File "/home/work/learning/tasks/book_app2/.venv/lib/python3.12/site-packages/django/core/handlers/base.py", line 220, in _get_response
    response = response.render()
               ^^^^^^^^^^^^^^^^^
  File "/home/work/learning/tasks/book_app2/.venv/lib/python3.12/site-packages/django/template/response.py", line 114, in render
    self.content = self.rendered_content
                   ^^^^^^^^^^^^^^^^^^^^^
  File "/home/work/learning/tasks/book_app2/.venv/lib/python3.12/site-packages/rest_framework/response.py", line 74, in rendered_content
    ret = renderer.render(self.data, accepted_media_type, context)
          ^^^^^^^^^^^^^^^^^^^^^^^^^^^^^^^^^^^^^^^^^^^^^^^^^^^^^^^^
  File "/home/work/learning/tasks/book_app2/.venv/lib/python3.12/site-packages/rest_framework/renderers.py", line 726, in render
    context = self.get_context(data, accepted_media_type, renderer_context)
              ^^^^^^^^^^^^^^^^^^^^^^^^^^^^^^^^^^^^^^^^^^^^^^^^^^^^^^^^^^^^^
  File "/home/work/learning/tasks/book_app2/.venv/lib/python3.12/site-packages/rest_framework/renderers.py", line 682, in get_context
    'content': self.get_content(renderer, data, accepted_media_type, renderer_context),
               ^^^^^^^^^^^^^^^^^^^^^^^^^^^^^^^^^^^^^^^^^^^^^^^^^^^^^^^^^^^^^^^^^^^^^^^
  File "/home/work/learning/tasks/book_app2/.venv/lib/python3.12/site-packages/rest_framework/renderers.py", line 412, in get_content
    content = renderer.render(data, accepted_media_type, renderer_context)
              ^^^^^^^^^^^^^^^^^^^^^^^^^^^^^^^^^^^^^^^^^^^^^^^^^^^^^^^^^^^^
  File "/home/work/learning/tasks/book_app2/.venv/lib/python3.12/site-packages/rest_framework/renderers.py", line 99, in render
    ret = json.dumps(
          ^^^^^^^^^^^
  File "/home/work/learning/tasks/book_app2/.venv/lib/python3.12/site-packages/rest_framework/utils/json.py", line 25, in dumps
    return json.dumps(*args, **kwargs)
           ^^^^^^^^^^^^^^^^^^^^^^^^^^^
  File "/usr/lib/python3.12/json/__init__.py", line 238, in dumps
    **kw).encode(obj)
          ^^^^^^^^^^^
  File "/usr/lib/python3.12/json/encoder.py", line 202, in encode
    chunks = list(chunks)
             ^^^^^^^^^^^^
  File "/usr/lib/python3.12/json/encoder.py", line 432, in _iterencode
    yield from _iterencode_dict(o, _current_indent_level)
  File "/usr/lib/python3.12/json/encoder.py", line 406, in _iterencode_dict
    yield from chunks
  File "/usr/lib/python3.12/json/encoder.py", line 406, in _iterencode_dict
    yield from chunks
  File "/usr/lib/python3.12/json/encoder.py", line 439, in _iterencode
    o = _default(o)
        ^^^^^^^^^^^
  File "/home/work/learning/tasks/book_app2/.venv/lib/python3.12/site-packages/rest_framework/utils/encoders.py", line 67, in default
    return super().default(obj)
           ^^^^^^^^^^^^^^^^^^^^
  File "/usr/lib/python3.12/json/encoder.py", line 180, in default
    raise TypeError(f'Object of type {o.__class__.__name__} '
TypeError: Object of type TypeError is not JSON serializable
ERROR:books.helpers.logging_helper:BookView get :: exception::  can only concatenate str (not "ImageFieldFile") to str
ERROR:django.request:Internal Server Error: /api/v1/books/
Traceback (most recent call last):
  File "/home/work/learning/tasks/book_app2/.venv/lib/python3.12/site-packages/django/core/handlers/exception.py", line 55, in inner
    response = get_response(request)
               ^^^^^^^^^^^^^^^^^^^^^
  File "/home/work/learning/tasks/book_app2/.venv/lib/python3.12/site-packages/django/core/handlers/base.py", line 220, in _get_response
    response = response.render()
               ^^^^^^^^^^^^^^^^^
  File "/home/work/learning/tasks/book_app2/.venv/lib/python3.12/site-packages/django/template/response.py", line 114, in render
    self.content = self.rendered_content
                   ^^^^^^^^^^^^^^^^^^^^^
  File "/home/work/learning/tasks/book_app2/.venv/lib/python3.12/site-packages/rest_framework/response.py", line 74, in rendered_content
    ret = renderer.render(self.data, accepted_media_type, context)
          ^^^^^^^^^^^^^^^^^^^^^^^^^^^^^^^^^^^^^^^^^^^^^^^^^^^^^^^^
  File "/home/work/learning/tasks/book_app2/.venv/lib/python3.12/site-packages/rest_framework/renderers.py", line 726, in render
    context = self.get_context(data, accepted_media_type, renderer_context)
              ^^^^^^^^^^^^^^^^^^^^^^^^^^^^^^^^^^^^^^^^^^^^^^^^^^^^^^^^^^^^^
  File "/home/work/learning/tasks/book_app2/.venv/lib/python3.12/site-packages/rest_framework/renderers.py", line 682, in get_context
    'content': self.get_content(renderer, data, accepted_media_type, renderer_context),
               ^^^^^^^^^^^^^^^^^^^^^^^^^^^^^^^^^^^^^^^^^^^^^^^^^^^^^^^^^^^^^^^^^^^^^^^
  File "/home/work/learning/tasks/book_app2/.venv/lib/python3.12/site-packages/rest_framework/renderers.py", line 412, in get_content
    content = renderer.render(data, accepted_media_type, renderer_context)
              ^^^^^^^^^^^^^^^^^^^^^^^^^^^^^^^^^^^^^^^^^^^^^^^^^^^^^^^^^^^^
  File "/home/work/learning/tasks/book_app2/.venv/lib/python3.12/site-packages/rest_framework/renderers.py", line 99, in render
    ret = json.dumps(
          ^^^^^^^^^^^
  File "/home/work/learning/tasks/book_app2/.venv/lib/python3.12/site-packages/rest_framework/utils/json.py", line 25, in dumps
    return json.dumps(*args, **kwargs)
           ^^^^^^^^^^^^^^^^^^^^^^^^^^^
  File "/usr/lib/python3.12/json/__init__.py", line 238, in dumps
    **kw).encode(obj)
          ^^^^^^^^^^^
  File "/usr/lib/python3.12/json/encoder.py", line 202, in encode
    chunks = list(chunks)
             ^^^^^^^^^^^^
  File "/usr/lib/python3.12/json/encoder.py", line 432, in _iterencode
    yield from _iterencode_dict(o, _current_indent_level)
  File "/usr/lib/python3.12/json/encoder.py", line 406, in _iterencode_dict
    yield from chunks
  File "/usr/lib/python3.12/json/encoder.py", line 406, in _iterencode_dict
    yield from chunks
  File "/usr/lib/python3.12/json/encoder.py", line 439, in _iterencode
    o = _default(o)
        ^^^^^^^^^^^
  File "/home/work/learning/tasks/book_app2/.venv/lib/python3.12/site-packages/rest_framework/utils/encoders.py", line 67, in default
    return super().default(obj)
           ^^^^^^^^^^^^^^^^^^^^
  File "/usr/lib/python3.12/json/encoder.py", line 180, in default
    raise TypeError(f'Object of type {o.__class__.__name__} '
TypeError: Object of type TypeError is not JSON serializable
ERROR:books.helpers.logging_helper:BookView get :: exception::  can only concatenate str (not "ImageFieldFile") to str
ERROR:django.request:Internal Server Error: /api/v1/books/
Traceback (most recent call last):
  File "/home/work/learning/tasks/book_app2/.venv/lib/python3.12/site-packages/django/core/handlers/exception.py", line 55, in inner
    response = get_response(request)
               ^^^^^^^^^^^^^^^^^^^^^
  File "/home/work/learning/tasks/book_app2/.venv/lib/python3.12/site-packages/django/core/handlers/base.py", line 220, in _get_response
    response = response.render()
               ^^^^^^^^^^^^^^^^^
  File "/home/work/learning/tasks/book_app2/.venv/lib/python3.12/site-packages/django/template/response.py", line 114, in render
    self.content = self.rendered_content
                   ^^^^^^^^^^^^^^^^^^^^^
  File "/home/work/learning/tasks/book_app2/.venv/lib/python3.12/site-packages/rest_framework/response.py", line 74, in rendered_content
    ret = renderer.render(self.data, accepted_media_type, context)
          ^^^^^^^^^^^^^^^^^^^^^^^^^^^^^^^^^^^^^^^^^^^^^^^^^^^^^^^^
  File "/home/work/learning/tasks/book_app2/.venv/lib/python3.12/site-packages/rest_framework/renderers.py", line 726, in render
    context = self.get_context(data, accepted_media_type, renderer_context)
              ^^^^^^^^^^^^^^^^^^^^^^^^^^^^^^^^^^^^^^^^^^^^^^^^^^^^^^^^^^^^^
  File "/home/work/learning/tasks/book_app2/.venv/lib/python3.12/site-packages/rest_framework/renderers.py", line 682, in get_context
    'content': self.get_content(renderer, data, accepted_media_type, renderer_context),
               ^^^^^^^^^^^^^^^^^^^^^^^^^^^^^^^^^^^^^^^^^^^^^^^^^^^^^^^^^^^^^^^^^^^^^^^
  File "/home/work/learning/tasks/book_app2/.venv/lib/python3.12/site-packages/rest_framework/renderers.py", line 412, in get_content
    content = renderer.render(data, accepted_media_type, renderer_context)
              ^^^^^^^^^^^^^^^^^^^^^^^^^^^^^^^^^^^^^^^^^^^^^^^^^^^^^^^^^^^^
  File "/home/work/learning/tasks/book_app2/.venv/lib/python3.12/site-packages/rest_framework/renderers.py", line 99, in render
    ret = json.dumps(
          ^^^^^^^^^^^
  File "/home/work/learning/tasks/book_app2/.venv/lib/python3.12/site-packages/rest_framework/utils/json.py", line 25, in dumps
    return json.dumps(*args, **kwargs)
           ^^^^^^^^^^^^^^^^^^^^^^^^^^^
  File "/usr/lib/python3.12/json/__init__.py", line 238, in dumps
    **kw).encode(obj)
          ^^^^^^^^^^^
  File "/usr/lib/python3.12/json/encoder.py", line 202, in encode
    chunks = list(chunks)
             ^^^^^^^^^^^^
  File "/usr/lib/python3.12/json/encoder.py", line 432, in _iterencode
    yield from _iterencode_dict(o, _current_indent_level)
  File "/usr/lib/python3.12/json/encoder.py", line 406, in _iterencode_dict
    yield from chunks
  File "/usr/lib/python3.12/json/encoder.py", line 406, in _iterencode_dict
    yield from chunks
  File "/usr/lib/python3.12/json/encoder.py", line 439, in _iterencode
    o = _default(o)
        ^^^^^^^^^^^
  File "/home/work/learning/tasks/book_app2/.venv/lib/python3.12/site-packages/rest_framework/utils/encoders.py", line 67, in default
    return super().default(obj)
           ^^^^^^^^^^^^^^^^^^^^
  File "/usr/lib/python3.12/json/encoder.py", line 180, in default
    raise TypeError(f'Object of type {o.__class__.__name__} '
TypeError: Object of type TypeError is not JSON serializable
INFO:django.utils.autoreload:/home/work/learning/tasks/book_app2/books/views/book_api.py changed, reloading.
ERROR:books.helpers.logging_helper:BookView get :: exception::  can only concatenate str (not "ImageFieldFile") to str
WARNING:django.request:Bad Request: /api/v1/books/
INFO:django.utils.autoreload:/home/work/learning/tasks/book_app2/books/services/book_service.py changed, reloading.
ERROR:books.helpers.logging_helper:BookView get :: exception::  Field source for `BookSerializer.title` maps to a built-in function type and is invalid. Define a property or method on the `str` instance that wraps the call to the built-in function.
WARNING:django.request:Bad Request: /api/v1/books/
INFO:django.utils.autoreload:/home/work/learning/tasks/book_app2/books/services/book_service.py changed, reloading.
INFO:django.utils.autoreload:/home/work/learning/tasks/book_app2/books/views/book_api.py changed, reloading.
INFO:django.utils.autoreload:/home/work/learning/tasks/book_app2/books/views/book_api.py changed, reloading.
INFO:django.utils.autoreload:/home/work/learning/tasks/book_app2/books/views/book_api.py changed, reloading.
INFO:django.utils.autoreload:/home/work/learning/tasks/book_app2/books/views/book_api.py changed, reloading.
INFO:django.utils.autoreload:/home/work/learning/tasks/book_app2/books/views/book_api.py changed, reloading.
INFO:django.utils.autoreload:/home/work/learning/tasks/book_app2/books/views/book_api.py changed, reloading.
INFO:django.utils.autoreload:/home/work/learning/tasks/book_app2/books/views/book_api.py changed, reloading.
INFO:django.utils.autoreload:/home/work/learning/tasks/book_app2/books/services/book_service.py changed, reloading.
INFO:django.utils.autoreload:/home/work/learning/tasks/book_app2/books/services/book_service.py changed, reloading.
INFO:django.utils.autoreload:/home/work/learning/tasks/book_app2/books/views/book_api.py changed, reloading.
INFO:django.utils.autoreload:/home/work/learning/tasks/book_app2/books/views/book_api.py changed, reloading.
INFO:django.utils.autoreload:/home/work/learning/tasks/book_app2/books/services/book_service.py changed, reloading.
INFO:django.utils.autoreload:/home/work/learning/tasks/book_app2/books/services/book_service.py changed, reloading.
INFO:django.utils.autoreload:/home/work/learning/tasks/book_app2/books/services/book_service.py changed, reloading.
INFO:django.utils.autoreload:/home/work/learning/tasks/book_app2/books/views/book_api.py changed, reloading.
ERROR:django.request:Internal Server Error: /api/v1/books/3c4b725d-55cf-4dcc-a83c-e35c83655484/
Traceback (most recent call last):
  File "/home/work/learning/tasks/book_app2/.venv/lib/python3.12/site-packages/django/core/handlers/exception.py", line 55, in inner
    response = get_response(request)
               ^^^^^^^^^^^^^^^^^^^^^
  File "/home/work/learning/tasks/book_app2/.venv/lib/python3.12/site-packages/django/core/handlers/base.py", line 197, in _get_response
    response = wrapped_callback(request, *callback_args, **callback_kwargs)
               ^^^^^^^^^^^^^^^^^^^^^^^^^^^^^^^^^^^^^^^^^^^^^^^^^^^^^^^^^^^^
  File "/home/work/learning/tasks/book_app2/.venv/lib/python3.12/site-packages/django/views/decorators/csrf.py", line 65, in _view_wrapper
    return view_func(request, *args, **kwargs)
           ^^^^^^^^^^^^^^^^^^^^^^^^^^^^^^^^^^^
  File "/home/work/learning/tasks/book_app2/.venv/lib/python3.12/site-packages/django/views/generic/base.py", line 104, in view
    return self.dispatch(request, *args, **kwargs)
           ^^^^^^^^^^^^^^^^^^^^^^^^^^^^^^^^^^^^^^^
  File "/home/work/learning/tasks/book_app2/.venv/lib/python3.12/site-packages/rest_framework/views.py", line 509, in dispatch
    response = self.handle_exception(exc)
               ^^^^^^^^^^^^^^^^^^^^^^^^^^
  File "/home/work/learning/tasks/book_app2/.venv/lib/python3.12/site-packages/rest_framework/views.py", line 469, in handle_exception
    self.raise_uncaught_exception(exc)
  File "/home/work/learning/tasks/book_app2/.venv/lib/python3.12/site-packages/rest_framework/views.py", line 480, in raise_uncaught_exception
    raise exc
  File "/home/work/learning/tasks/book_app2/.venv/lib/python3.12/site-packages/rest_framework/views.py", line 506, in dispatch
    response = handler(request, *args, **kwargs)
               ^^^^^^^^^^^^^^^^^^^^^^^^^^^^^^^^^
  File "/home/work/learning/tasks/book_app2/.venv/lib/python3.12/site-packages/rest_framework/decorators.py", line 50, in handler
    return func(*args, **kwargs)
           ^^^^^^^^^^^^^^^^^^^^^
  File "/home/work/learning/tasks/book_app2/books/views/book_api.py", line 42, in book_detail
    book = book_service.update_book(old_data=book, new_data=request.data)
           ^^^^^^^^^^^^^^^^^^^^^^^^^^^^^^^^^^^^^^^^^^^^^^^^^^^^^^^^^^^^^^
  File "/home/work/learning/tasks/book_app2/books/services/book_service.py", line 36, in update_book
    serializer.save()
  File "/home/work/learning/tasks/book_app2/.venv/lib/python3.12/site-packages/rest_framework/serializers.py", line 203, in save
    self.instance = self.update(self.instance, validated_data)
                    ^^^^^^^^^^^^^^^^^^^^^^^^^^^^^^^^^^^^^^^^^^
  File "/home/work/learning/tasks/book_app2/.venv/lib/python3.12/site-packages/rest_framework/serializers.py", line 1020, in update
    info = model_meta.get_field_info(instance)
           ^^^^^^^^^^^^^^^^^^^^^^^^^^^^^^^^^^^
  File "/home/work/learning/tasks/book_app2/.venv/lib/python3.12/site-packages/rest_framework/utils/model_meta.py", line 35, in get_field_info
    opts = model._meta.concrete_model._meta
           ^^^^^^^^^^^
AttributeError: 'ReturnDict' object has no attribute '_meta'
INFO:django.utils.autoreload:/home/work/learning/tasks/book_app2/books/views/book_api.py changed, reloading.
WARNING:django.request:Method Not Allowed: /api/v1/books/3c4b725d-55cf-4dcc-a83c-e35c83655484/
ERROR:django.request:Internal Server Error: /api/v1/books/3c4b725d-55cf-4dcc-a83c-e35c83655484/
Traceback (most recent call last):
  File "/home/work/learning/tasks/book_app2/.venv/lib/python3.12/site-packages/django/core/handlers/exception.py", line 55, in inner
    response = get_response(request)
               ^^^^^^^^^^^^^^^^^^^^^
  File "/home/work/learning/tasks/book_app2/.venv/lib/python3.12/site-packages/django/core/handlers/base.py", line 197, in _get_response
    response = wrapped_callback(request, *callback_args, **callback_kwargs)
               ^^^^^^^^^^^^^^^^^^^^^^^^^^^^^^^^^^^^^^^^^^^^^^^^^^^^^^^^^^^^
  File "/home/work/learning/tasks/book_app2/.venv/lib/python3.12/site-packages/django/views/decorators/csrf.py", line 65, in _view_wrapper
    return view_func(request, *args, **kwargs)
           ^^^^^^^^^^^^^^^^^^^^^^^^^^^^^^^^^^^
  File "/home/work/learning/tasks/book_app2/.venv/lib/python3.12/site-packages/django/views/generic/base.py", line 104, in view
    return self.dispatch(request, *args, **kwargs)
           ^^^^^^^^^^^^^^^^^^^^^^^^^^^^^^^^^^^^^^^
  File "/home/work/learning/tasks/book_app2/.venv/lib/python3.12/site-packages/rest_framework/views.py", line 509, in dispatch
    response = self.handle_exception(exc)
               ^^^^^^^^^^^^^^^^^^^^^^^^^^
  File "/home/work/learning/tasks/book_app2/.venv/lib/python3.12/site-packages/rest_framework/views.py", line 469, in handle_exception
    self.raise_uncaught_exception(exc)
  File "/home/work/learning/tasks/book_app2/.venv/lib/python3.12/site-packages/rest_framework/views.py", line 480, in raise_uncaught_exception
    raise exc
  File "/home/work/learning/tasks/book_app2/.venv/lib/python3.12/site-packages/rest_framework/views.py", line 506, in dispatch
    response = handler(request, *args, **kwargs)
               ^^^^^^^^^^^^^^^^^^^^^^^^^^^^^^^^^
  File "/home/work/learning/tasks/book_app2/.venv/lib/python3.12/site-packages/rest_framework/decorators.py", line 50, in handler
    return func(*args, **kwargs)
           ^^^^^^^^^^^^^^^^^^^^^
  File "/home/work/learning/tasks/book_app2/books/views/book_api.py", line 43, in book_detail
    book = book_service.update_book(old_data=book, new_data=request.data)
           ^^^^^^^^^^^^^^^^^^^^^^^^^^^^^^^^^^^^^^^^^^^^^^^^^^^^^^^^^^^^^^
  File "/home/work/learning/tasks/book_app2/books/services/book_service.py", line 36, in update_book
    serializer.save()
  File "/home/work/learning/tasks/book_app2/.venv/lib/python3.12/site-packages/rest_framework/serializers.py", line 203, in save
    self.instance = self.update(self.instance, validated_data)
                    ^^^^^^^^^^^^^^^^^^^^^^^^^^^^^^^^^^^^^^^^^^
  File "/home/work/learning/tasks/book_app2/.venv/lib/python3.12/site-packages/rest_framework/serializers.py", line 1020, in update
    info = model_meta.get_field_info(instance)
           ^^^^^^^^^^^^^^^^^^^^^^^^^^^^^^^^^^^
  File "/home/work/learning/tasks/book_app2/.venv/lib/python3.12/site-packages/rest_framework/utils/model_meta.py", line 35, in get_field_info
    opts = model._meta.concrete_model._meta
           ^^^^^^^^^^^
AttributeError: 'ReturnDict' object has no attribute '_meta'
INFO:django.utils.autoreload:/home/work/learning/tasks/book_app2/books/views/book_api.py changed, reloading.
ERROR:django.request:Internal Server Error: /api/v1/books/3c4b725d-55cf-4dcc-a83c-e35c83655484/
Traceback (most recent call last):
  File "/home/work/learning/tasks/book_app2/.venv/lib/python3.12/site-packages/django/core/handlers/exception.py", line 55, in inner
    response = get_response(request)
               ^^^^^^^^^^^^^^^^^^^^^
  File "/home/work/learning/tasks/book_app2/.venv/lib/python3.12/site-packages/django/core/handlers/base.py", line 197, in _get_response
    response = wrapped_callback(request, *callback_args, **callback_kwargs)
               ^^^^^^^^^^^^^^^^^^^^^^^^^^^^^^^^^^^^^^^^^^^^^^^^^^^^^^^^^^^^
  File "/home/work/learning/tasks/book_app2/.venv/lib/python3.12/site-packages/django/views/decorators/csrf.py", line 65, in _view_wrapper
    return view_func(request, *args, **kwargs)
           ^^^^^^^^^^^^^^^^^^^^^^^^^^^^^^^^^^^
  File "/home/work/learning/tasks/book_app2/.venv/lib/python3.12/site-packages/django/views/generic/base.py", line 104, in view
    return self.dispatch(request, *args, **kwargs)
           ^^^^^^^^^^^^^^^^^^^^^^^^^^^^^^^^^^^^^^^
  File "/home/work/learning/tasks/book_app2/.venv/lib/python3.12/site-packages/rest_framework/views.py", line 509, in dispatch
    response = self.handle_exception(exc)
               ^^^^^^^^^^^^^^^^^^^^^^^^^^
  File "/home/work/learning/tasks/book_app2/.venv/lib/python3.12/site-packages/rest_framework/views.py", line 469, in handle_exception
    self.raise_uncaught_exception(exc)
  File "/home/work/learning/tasks/book_app2/.venv/lib/python3.12/site-packages/rest_framework/views.py", line 480, in raise_uncaught_exception
    raise exc
  File "/home/work/learning/tasks/book_app2/.venv/lib/python3.12/site-packages/rest_framework/views.py", line 506, in dispatch
    response = handler(request, *args, **kwargs)
               ^^^^^^^^^^^^^^^^^^^^^^^^^^^^^^^^^
  File "/home/work/learning/tasks/book_app2/.venv/lib/python3.12/site-packages/rest_framework/decorators.py", line 50, in handler
    return func(*args, **kwargs)
           ^^^^^^^^^^^^^^^^^^^^^
  File "/home/work/learning/tasks/book_app2/books/views/book_api.py", line 43, in book_detail
    book = book_service.update_book(old_data=book, new_data=request.data)
           ^^^^^^^^^^^^^^^^^^^^^^^^^^^^^^^^^^^^^^^^^^^^^^^^^^^^^^^^^^^^^^
  File "/home/work/learning/tasks/book_app2/books/services/book_service.py", line 36, in update_book
    serializer.save()
  File "/home/work/learning/tasks/book_app2/.venv/lib/python3.12/site-packages/rest_framework/serializers.py", line 203, in save
    self.instance = self.update(self.instance, validated_data)
                    ^^^^^^^^^^^^^^^^^^^^^^^^^^^^^^^^^^^^^^^^^^
  File "/home/work/learning/tasks/book_app2/.venv/lib/python3.12/site-packages/rest_framework/serializers.py", line 1020, in update
    info = model_meta.get_field_info(instance)
           ^^^^^^^^^^^^^^^^^^^^^^^^^^^^^^^^^^^
  File "/home/work/learning/tasks/book_app2/.venv/lib/python3.12/site-packages/rest_framework/utils/model_meta.py", line 35, in get_field_info
    opts = model._meta.concrete_model._meta
           ^^^^^^^^^^^
AttributeError: 'ReturnDict' object has no attribute '_meta'
INFO:django.utils.autoreload:/home/work/learning/tasks/book_app2/books/views/book_api.py changed, reloading.
INFO:django.utils.autoreload:/home/work/learning/tasks/book_app2/books/views/book_api.py changed, reloading.
INFO:django.utils.autoreload:/home/work/learning/tasks/book_app2/books/services/book_service.py changed, reloading.
INFO:django.utils.autoreload:/home/work/learning/tasks/book_app2/books/services/book_service.py changed, reloading.
INFO:books.helpers.logging_helper:Book Updated
ERROR:django.request:Internal Server Error: /api/v1/books/3c4b725d-55cf-4dcc-a83c-e35c83655484/
Traceback (most recent call last):
  File "/home/work/learning/tasks/book_app2/.venv/lib/python3.12/site-packages/django/core/handlers/exception.py", line 55, in inner
    response = get_response(request)
               ^^^^^^^^^^^^^^^^^^^^^
  File "/home/work/learning/tasks/book_app2/.venv/lib/python3.12/site-packages/django/core/handlers/base.py", line 197, in _get_response
    response = wrapped_callback(request, *callback_args, **callback_kwargs)
               ^^^^^^^^^^^^^^^^^^^^^^^^^^^^^^^^^^^^^^^^^^^^^^^^^^^^^^^^^^^^
  File "/home/work/learning/tasks/book_app2/.venv/lib/python3.12/site-packages/django/views/decorators/csrf.py", line 65, in _view_wrapper
    return view_func(request, *args, **kwargs)
           ^^^^^^^^^^^^^^^^^^^^^^^^^^^^^^^^^^^
  File "/home/work/learning/tasks/book_app2/.venv/lib/python3.12/site-packages/django/views/generic/base.py", line 104, in view
    return self.dispatch(request, *args, **kwargs)
           ^^^^^^^^^^^^^^^^^^^^^^^^^^^^^^^^^^^^^^^
  File "/home/work/learning/tasks/book_app2/.venv/lib/python3.12/site-packages/rest_framework/views.py", line 511, in dispatch
    self.response = self.finalize_response(request, response, *args, **kwargs)
                    ^^^^^^^^^^^^^^^^^^^^^^^^^^^^^^^^^^^^^^^^^^^^^^^^^^^^^^^^^^
  File "/home/work/learning/tasks/book_app2/.venv/lib/python3.12/site-packages/rest_framework/views.py", line 423, in finalize_response
    assert isinstance(response, HttpResponseBase), (
           ^^^^^^^^^^^^^^^^^^^^^^^^^^^^^^^^^^^^^^
AssertionError: Expected a `Response`, `HttpResponse` or `StreamingHttpResponse` to be returned from the view, but received a `<class 'NoneType'>`
INFO:django.utils.autoreload:/home/work/learning/tasks/book_app2/books/views/book_api.py changed, reloading.
INFO:django.utils.autoreload:/home/work/learning/tasks/book_app2/books/services/book_service.py changed, reloading.
INFO:books.helpers.logging_helper:Book Updated
ERROR:django.request:Internal Server Error: /api/v1/books/3c4b725d-55cf-4dcc-a83c-e35c83655484/
Traceback (most recent call last):
  File "/home/work/learning/tasks/book_app2/.venv/lib/python3.12/site-packages/django/core/handlers/exception.py", line 55, in inner
    response = get_response(request)
               ^^^^^^^^^^^^^^^^^^^^^
  File "/home/work/learning/tasks/book_app2/.venv/lib/python3.12/site-packages/django/core/handlers/base.py", line 197, in _get_response
    response = wrapped_callback(request, *callback_args, **callback_kwargs)
               ^^^^^^^^^^^^^^^^^^^^^^^^^^^^^^^^^^^^^^^^^^^^^^^^^^^^^^^^^^^^
  File "/home/work/learning/tasks/book_app2/.venv/lib/python3.12/site-packages/django/views/decorators/csrf.py", line 65, in _view_wrapper
    return view_func(request, *args, **kwargs)
           ^^^^^^^^^^^^^^^^^^^^^^^^^^^^^^^^^^^
  File "/home/work/learning/tasks/book_app2/.venv/lib/python3.12/site-packages/django/views/generic/base.py", line 104, in view
    return self.dispatch(request, *args, **kwargs)
           ^^^^^^^^^^^^^^^^^^^^^^^^^^^^^^^^^^^^^^^
  File "/home/work/learning/tasks/book_app2/.venv/lib/python3.12/site-packages/rest_framework/views.py", line 511, in dispatch
    self.response = self.finalize_response(request, response, *args, **kwargs)
                    ^^^^^^^^^^^^^^^^^^^^^^^^^^^^^^^^^^^^^^^^^^^^^^^^^^^^^^^^^^
  File "/home/work/learning/tasks/book_app2/.venv/lib/python3.12/site-packages/rest_framework/views.py", line 423, in finalize_response
    assert isinstance(response, HttpResponseBase), (
           ^^^^^^^^^^^^^^^^^^^^^^^^^^^^^^^^^^^^^^
AssertionError: Expected a `Response`, `HttpResponse` or `StreamingHttpResponse` to be returned from the view, but received a `<class 'NoneType'>`
INFO:django.utils.autoreload:/home/work/learning/tasks/book_app2/books/services/book_service.py changed, reloading.
INFO:books.helpers.logging_helper:Book Updated
ERROR:django.request:Internal Server Error: /api/v1/books/3c4b725d-55cf-4dcc-a83c-e35c83655484/
Traceback (most recent call last):
  File "/home/work/learning/tasks/book_app2/.venv/lib/python3.12/site-packages/django/core/handlers/exception.py", line 55, in inner
    response = get_response(request)
               ^^^^^^^^^^^^^^^^^^^^^
  File "/home/work/learning/tasks/book_app2/.venv/lib/python3.12/site-packages/django/core/handlers/base.py", line 197, in _get_response
    response = wrapped_callback(request, *callback_args, **callback_kwargs)
               ^^^^^^^^^^^^^^^^^^^^^^^^^^^^^^^^^^^^^^^^^^^^^^^^^^^^^^^^^^^^
  File "/home/work/learning/tasks/book_app2/.venv/lib/python3.12/site-packages/django/views/decorators/csrf.py", line 65, in _view_wrapper
    return view_func(request, *args, **kwargs)
           ^^^^^^^^^^^^^^^^^^^^^^^^^^^^^^^^^^^
  File "/home/work/learning/tasks/book_app2/.venv/lib/python3.12/site-packages/django/views/generic/base.py", line 104, in view
    return self.dispatch(request, *args, **kwargs)
           ^^^^^^^^^^^^^^^^^^^^^^^^^^^^^^^^^^^^^^^
  File "/home/work/learning/tasks/book_app2/.venv/lib/python3.12/site-packages/rest_framework/views.py", line 511, in dispatch
    self.response = self.finalize_response(request, response, *args, **kwargs)
                    ^^^^^^^^^^^^^^^^^^^^^^^^^^^^^^^^^^^^^^^^^^^^^^^^^^^^^^^^^^
  File "/home/work/learning/tasks/book_app2/.venv/lib/python3.12/site-packages/rest_framework/views.py", line 423, in finalize_response
    assert isinstance(response, HttpResponseBase), (
           ^^^^^^^^^^^^^^^^^^^^^^^^^^^^^^^^^^^^^^
AssertionError: Expected a `Response`, `HttpResponse` or `StreamingHttpResponse` to be returned from the view, but received a `<class 'NoneType'>`
INFO:django.utils.autoreload:/home/work/learning/tasks/book_app2/books/services/book_service.py changed, reloading.
INFO:django.utils.autoreload:/home/work/learning/tasks/book_app2/books/services/book_service.py changed, reloading.
ERROR:books.helpers.logging_helper:BookService.updated_book :: ValueError
ERROR:django.request:Internal Server Error: /api/v1/books/3c4b725d-55cf-4dcc-a83c-e35c83655484/
Traceback (most recent call last):
  File "/home/work/learning/tasks/book_app2/.venv/lib/python3.12/site-packages/django/core/handlers/exception.py", line 55, in inner
    response = get_response(request)
               ^^^^^^^^^^^^^^^^^^^^^
  File "/home/work/learning/tasks/book_app2/.venv/lib/python3.12/site-packages/django/core/handlers/base.py", line 197, in _get_response
    response = wrapped_callback(request, *callback_args, **callback_kwargs)
               ^^^^^^^^^^^^^^^^^^^^^^^^^^^^^^^^^^^^^^^^^^^^^^^^^^^^^^^^^^^^
  File "/home/work/learning/tasks/book_app2/.venv/lib/python3.12/site-packages/django/views/decorators/csrf.py", line 65, in _view_wrapper
    return view_func(request, *args, **kwargs)
           ^^^^^^^^^^^^^^^^^^^^^^^^^^^^^^^^^^^
  File "/home/work/learning/tasks/book_app2/.venv/lib/python3.12/site-packages/django/views/generic/base.py", line 104, in view
    return self.dispatch(request, *args, **kwargs)
           ^^^^^^^^^^^^^^^^^^^^^^^^^^^^^^^^^^^^^^^
  File "/home/work/learning/tasks/book_app2/.venv/lib/python3.12/site-packages/rest_framework/views.py", line 509, in dispatch
    response = self.handle_exception(exc)
               ^^^^^^^^^^^^^^^^^^^^^^^^^^
  File "/home/work/learning/tasks/book_app2/.venv/lib/python3.12/site-packages/rest_framework/views.py", line 469, in handle_exception
    self.raise_uncaught_exception(exc)
  File "/home/work/learning/tasks/book_app2/.venv/lib/python3.12/site-packages/rest_framework/views.py", line 480, in raise_uncaught_exception
    raise exc
  File "/home/work/learning/tasks/book_app2/.venv/lib/python3.12/site-packages/rest_framework/views.py", line 506, in dispatch
    response = handler(request, *args, **kwargs)
               ^^^^^^^^^^^^^^^^^^^^^^^^^^^^^^^^^
  File "/home/work/learning/tasks/book_app2/.venv/lib/python3.12/site-packages/rest_framework/decorators.py", line 50, in handler
    return func(*args, **kwargs)
           ^^^^^^^^^^^^^^^^^^^^^
  File "/home/work/learning/tasks/book_app2/books/views/book_api.py", line 42, in book_detail
    book = book_service.update_book(book_idx=idx, new_data=request.data)
           ^^^^^^^^^^^^^^^^^^^^^^^^^^^^^^^^^^^^^^^^^^^^^^^^^^^^^^^^^^^^^
  File "/home/work/learning/tasks/book_app2/books/services/book_service.py", line 42, in update_book
    raise ValueError
ValueError
INFO:django.utils.autoreload:/home/work/learning/tasks/book_app2/books/views/book_api.py changed, reloading.
INFO:django.utils.autoreload:/home/work/learning/tasks/book_app2/books/views/book_api.py changed, reloading.
INFO:django.utils.autoreload:/home/work/learning/tasks/book_app2/books/views/book_api.py changed, reloading.
ERROR:books.helpers.logging_helper:BookService.updated_book :: ValueError
INFO:django.utils.autoreload:/home/work/learning/tasks/book_app2/books/views/book_api.py changed, reloading.
ERROR:books.helpers.logging_helper:BookService.updated_book :: ValueError
ERROR:django.request:Internal Server Error: /api/v1/books/3c4b725d-55cf-4dcc-a83c-e35c83655484/
Traceback (most recent call last):
  File "/home/work/learning/tasks/book_app2/books/views/book_api.py", line 43, in book_detail
    book = book_service.update_book(book_idx=idx, new_data=request.data)
           ^^^^^^^^^^^^^^^^^^^^^^^^^^^^^^^^^^^^^^^^^^^^^^^^^^^^^^^^^^^^^
  File "/home/work/learning/tasks/book_app2/books/services/book_service.py", line 42, in update_book
    raise ValueError
ValueError

During handling of the above exception, another exception occurred:

Traceback (most recent call last):
  File "/home/work/learning/tasks/book_app2/.venv/lib/python3.12/site-packages/django/core/handlers/exception.py", line 55, in inner
    response = get_response(request)
               ^^^^^^^^^^^^^^^^^^^^^
  File "/home/work/learning/tasks/book_app2/.venv/lib/python3.12/site-packages/django/core/handlers/base.py", line 197, in _get_response
    response = wrapped_callback(request, *callback_args, **callback_kwargs)
               ^^^^^^^^^^^^^^^^^^^^^^^^^^^^^^^^^^^^^^^^^^^^^^^^^^^^^^^^^^^^
  File "/home/work/learning/tasks/book_app2/.venv/lib/python3.12/site-packages/django/views/decorators/csrf.py", line 65, in _view_wrapper
    return view_func(request, *args, **kwargs)
           ^^^^^^^^^^^^^^^^^^^^^^^^^^^^^^^^^^^
  File "/home/work/learning/tasks/book_app2/.venv/lib/python3.12/site-packages/django/views/generic/base.py", line 104, in view
    return self.dispatch(request, *args, **kwargs)
           ^^^^^^^^^^^^^^^^^^^^^^^^^^^^^^^^^^^^^^^
  File "/home/work/learning/tasks/book_app2/.venv/lib/python3.12/site-packages/rest_framework/views.py", line 509, in dispatch
    response = self.handle_exception(exc)
               ^^^^^^^^^^^^^^^^^^^^^^^^^^
  File "/home/work/learning/tasks/book_app2/.venv/lib/python3.12/site-packages/rest_framework/views.py", line 469, in handle_exception
    self.raise_uncaught_exception(exc)
  File "/home/work/learning/tasks/book_app2/.venv/lib/python3.12/site-packages/rest_framework/views.py", line 480, in raise_uncaught_exception
    raise exc
  File "/home/work/learning/tasks/book_app2/.venv/lib/python3.12/site-packages/rest_framework/views.py", line 506, in dispatch
    response = handler(request, *args, **kwargs)
               ^^^^^^^^^^^^^^^^^^^^^^^^^^^^^^^^^
  File "/home/work/learning/tasks/book_app2/.venv/lib/python3.12/site-packages/rest_framework/decorators.py", line 50, in handler
    return func(*args, **kwargs)
           ^^^^^^^^^^^^^^^^^^^^^
  File "/home/work/learning/tasks/book_app2/books/views/book_api.py", line 45, in book_detail
    return response_builder.result_object({"error": f"Exception Occured: {e}"}).get_response()
                                                                          ^
UnboundLocalError: cannot access local variable 'e' where it is not associated with a value
INFO:django.utils.autoreload:/home/work/learning/tasks/book_app2/books/views/book_api.py changed, reloading.
ERROR:books.helpers.logging_helper:BookService.updated_book :: ValueError
INFO:django.utils.autoreload:/home/work/learning/tasks/book_app2/books/views/book_api.py changed, reloading.
ERROR:books.helpers.logging_helper:BookService.updated_book :: ValueError
INFO:django.utils.autoreload:/home/work/learning/tasks/book_app2/books/services/book_service.py changed, reloading.
INFO:django.utils.autoreload:/home/work/learning/tasks/book_app2/books/views/book_api.py changed, reloading.
ERROR:books.helpers.logging_helper:BookService.updated_book :: ValueError
INFO:django.utils.autoreload:/home/work/learning/tasks/book_app2/books/services/book_service.py changed, reloading.
INFO:books.helpers.logging_helper:Book Updated
INFO:books.helpers.logging_helper:Book Updated
INFO:django.utils.autoreload:/home/work/learning/tasks/book_app2/books/views/book_api.py changed, reloading.
INFO:books.helpers.logging_helper:Book Updated
INFO:django.utils.autoreload:/home/work/learning/tasks/book_app2/books/services/book_service.py changed, reloading.
ERROR:books.helpers.logging_helper:BookService.updated_book :: ValueError
INFO:django.utils.autoreload:/home/work/learning/tasks/book_app2/books/services/book_service.py changed, reloading.
INFO:django.utils.autoreload:/home/work/learning/tasks/book_app2/books/services/book_service.py changed, reloading.
INFO:django.utils.autoreload:/home/work/learning/tasks/book_app2/books/views/book_api.py changed, reloading.
INFO:django.utils.autoreload:/home/work/learning/tasks/book_app2/books/views/book_api.py changed, reloading.
INFO:django.utils.autoreload:/home/work/learning/tasks/book_app2/books/views/book_api.py changed, reloading.
INFO:books.helpers.logging_helper:Book Updated
INFO:books.helpers.logging_helper:Book Updated
ERROR:django.request:Internal Server Error: /api/v1/books/3c4b725d-55cf-4dcc-a83c-e35c83655484/
Traceback (most recent call last):
  File "/home/work/learning/tasks/book_app2/.venv/lib/python3.12/site-packages/django/core/handlers/exception.py", line 55, in inner
    response = get_response(request)
               ^^^^^^^^^^^^^^^^^^^^^
  File "/home/work/learning/tasks/book_app2/.venv/lib/python3.12/site-packages/django/core/handlers/base.py", line 197, in _get_response
    response = wrapped_callback(request, *callback_args, **callback_kwargs)
               ^^^^^^^^^^^^^^^^^^^^^^^^^^^^^^^^^^^^^^^^^^^^^^^^^^^^^^^^^^^^
  File "/home/work/learning/tasks/book_app2/.venv/lib/python3.12/site-packages/django/views/decorators/csrf.py", line 65, in _view_wrapper
    return view_func(request, *args, **kwargs)
           ^^^^^^^^^^^^^^^^^^^^^^^^^^^^^^^^^^^
  File "/home/work/learning/tasks/book_app2/.venv/lib/python3.12/site-packages/django/views/generic/base.py", line 104, in view
    return self.dispatch(request, *args, **kwargs)
           ^^^^^^^^^^^^^^^^^^^^^^^^^^^^^^^^^^^^^^^
  File "/home/work/learning/tasks/book_app2/.venv/lib/python3.12/site-packages/rest_framework/views.py", line 511, in dispatch
    self.response = self.finalize_response(request, response, *args, **kwargs)
                    ^^^^^^^^^^^^^^^^^^^^^^^^^^^^^^^^^^^^^^^^^^^^^^^^^^^^^^^^^^
  File "/home/work/learning/tasks/book_app2/.venv/lib/python3.12/site-packages/rest_framework/views.py", line 423, in finalize_response
    assert isinstance(response, HttpResponseBase), (
           ^^^^^^^^^^^^^^^^^^^^^^^^^^^^^^^^^^^^^^
AssertionError: Expected a `Response`, `HttpResponse` or `StreamingHttpResponse` to be returned from the view, but received a `<class 'NoneType'>`
INFO:django.utils.autoreload:/home/work/learning/tasks/book_app2/books/views/book_api.py changed, reloading.
INFO:django.utils.autoreload:/home/work/learning/tasks/book_app2/books/views/book_api.py changed, reloading.
INFO:django.utils.autoreload:/home/work/learning/tasks/book_app2/books/services/book_service.py changed, reloading.
INFO:django.utils.autoreload:/home/work/learning/tasks/book_app2/books/services/book_service.py changed, reloading.
INFO:django.utils.autoreload:/home/work/learning/tasks/book_app2/books/services/book_service.py changed, reloading.
INFO:django.utils.autoreload:/home/work/learning/tasks/book_app2/books/services/book_service.py changed, reloading.
INFO:django.utils.autoreload:/home/work/learning/tasks/book_app2/books/services/book_service.py changed, reloading.
INFO:django.utils.autoreload:/home/work/learning/tasks/book_app2/books/views/book_api.py changed, reloading.
ERROR:django.request:Internal Server Error: /api/v1/books/3c4b725d-55cf-4dcc-a83c-e35c83655484/
Traceback (most recent call last):
  File "/home/work/learning/tasks/book_app2/.venv/lib/python3.12/site-packages/django/core/handlers/exception.py", line 55, in inner
    response = get_response(request)
               ^^^^^^^^^^^^^^^^^^^^^
  File "/home/work/learning/tasks/book_app2/.venv/lib/python3.12/site-packages/django/core/handlers/base.py", line 197, in _get_response
    response = wrapped_callback(request, *callback_args, **callback_kwargs)
               ^^^^^^^^^^^^^^^^^^^^^^^^^^^^^^^^^^^^^^^^^^^^^^^^^^^^^^^^^^^^
  File "/home/work/learning/tasks/book_app2/.venv/lib/python3.12/site-packages/django/views/decorators/csrf.py", line 65, in _view_wrapper
    return view_func(request, *args, **kwargs)
           ^^^^^^^^^^^^^^^^^^^^^^^^^^^^^^^^^^^
  File "/home/work/learning/tasks/book_app2/.venv/lib/python3.12/site-packages/django/views/generic/base.py", line 104, in view
    return self.dispatch(request, *args, **kwargs)
           ^^^^^^^^^^^^^^^^^^^^^^^^^^^^^^^^^^^^^^^
  File "/home/work/learning/tasks/book_app2/.venv/lib/python3.12/site-packages/rest_framework/views.py", line 509, in dispatch
    response = self.handle_exception(exc)
               ^^^^^^^^^^^^^^^^^^^^^^^^^^
  File "/home/work/learning/tasks/book_app2/.venv/lib/python3.12/site-packages/rest_framework/views.py", line 469, in handle_exception
    self.raise_uncaught_exception(exc)
  File "/home/work/learning/tasks/book_app2/.venv/lib/python3.12/site-packages/rest_framework/views.py", line 480, in raise_uncaught_exception
    raise exc
  File "/home/work/learning/tasks/book_app2/.venv/lib/python3.12/site-packages/rest_framework/views.py", line 506, in dispatch
    response = handler(request, *args, **kwargs)
               ^^^^^^^^^^^^^^^^^^^^^^^^^^^^^^^^^
  File "/home/work/learning/tasks/book_app2/.venv/lib/python3.12/site-packages/rest_framework/decorators.py", line 50, in handler
    return func(*args, **kwargs)
           ^^^^^^^^^^^^^^^^^^^^^
  File "/home/work/learning/tasks/book_app2/books/views/book_api.py", line 48, in book_detail
    book_service.delete_book(book_idx=idx)
  File "/home/work/learning/tasks/book_app2/books/services/book_service.py", line 54, in delete_book
    book = Book.objects.filer(idx=book_idx).first()
           ^^^^^^^^^^^^^^^^^^
AttributeError: 'Manager' object has no attribute 'filer'. Did you mean: 'filter'?
INFO:django.utils.autoreload:/home/work/learning/tasks/book_app2/books/services/book_service.py changed, reloading.
INFO:django.utils.autoreload:/home/work/learning/tasks/book_app2/books/services/book_service.py changed, reloading.
INFO:django.utils.autoreload:/home/work/learning/tasks/book_app2/books/views/book_api.py changed, reloading.
INFO:django.utils.autoreload:/home/work/learning/tasks/book_app2/books/views/book_api.py changed, reloading.
INFO:django.utils.autoreload:/home/work/learning/tasks/book_app2/books/services/book_service.py changed, reloading.
ERROR:books.helpers.logging_helper:BookDetailView get :: exception :: Book matching query does not exist.
ERROR:django.request:Internal Server Error: /api/v1/books/3c4b725d-55cf-4dcc-a83c-e35c83655484/
Traceback (most recent call last):
  File "/home/work/learning/tasks/book_app2/.venv/lib/python3.12/site-packages/django/core/handlers/exception.py", line 55, in inner
    response = get_response(request)
               ^^^^^^^^^^^^^^^^^^^^^
  File "/home/work/learning/tasks/book_app2/.venv/lib/python3.12/site-packages/django/core/handlers/base.py", line 220, in _get_response
    response = response.render()
               ^^^^^^^^^^^^^^^^^
  File "/home/work/learning/tasks/book_app2/.venv/lib/python3.12/site-packages/django/template/response.py", line 114, in render
    self.content = self.rendered_content
                   ^^^^^^^^^^^^^^^^^^^^^
  File "/home/work/learning/tasks/book_app2/.venv/lib/python3.12/site-packages/rest_framework/response.py", line 74, in rendered_content
    ret = renderer.render(self.data, accepted_media_type, context)
          ^^^^^^^^^^^^^^^^^^^^^^^^^^^^^^^^^^^^^^^^^^^^^^^^^^^^^^^^
  File "/home/work/learning/tasks/book_app2/.venv/lib/python3.12/site-packages/rest_framework/renderers.py", line 99, in render
    ret = json.dumps(
          ^^^^^^^^^^^
  File "/home/work/learning/tasks/book_app2/.venv/lib/python3.12/site-packages/rest_framework/utils/json.py", line 25, in dumps
    return json.dumps(*args, **kwargs)
           ^^^^^^^^^^^^^^^^^^^^^^^^^^^
  File "/usr/lib/python3.12/json/__init__.py", line 238, in dumps
    **kw).encode(obj)
          ^^^^^^^^^^^
  File "/usr/lib/python3.12/json/encoder.py", line 200, in encode
    chunks = self.iterencode(o, _one_shot=True)
             ^^^^^^^^^^^^^^^^^^^^^^^^^^^^^^^^^^
  File "/usr/lib/python3.12/json/encoder.py", line 258, in iterencode
    return _iterencode(o, 0)
           ^^^^^^^^^^^^^^^^^
  File "/home/work/learning/tasks/book_app2/.venv/lib/python3.12/site-packages/rest_framework/utils/encoders.py", line 67, in default
    return super().default(obj)
           ^^^^^^^^^^^^^^^^^^^^
  File "/usr/lib/python3.12/json/encoder.py", line 180, in default
    raise TypeError(f'Object of type {o.__class__.__name__} '
TypeError: Object of type DoesNotExist is not JSON serializable
INFO:django.utils.autoreload:/home/work/learning/tasks/book_app2/books/services/book_service.py changed, reloading.
ERROR:books.helpers.logging_helper:BookDetailView get :: exception :: Book matching query does not exist.
ERROR:django.request:Internal Server Error: /api/v1/books/3c4b725d-55cf-4dcc-a83c-e35c83655484/
Traceback (most recent call last):
  File "/home/work/learning/tasks/book_app2/.venv/lib/python3.12/site-packages/django/core/handlers/exception.py", line 55, in inner
    response = get_response(request)
               ^^^^^^^^^^^^^^^^^^^^^
  File "/home/work/learning/tasks/book_app2/.venv/lib/python3.12/site-packages/django/core/handlers/base.py", line 220, in _get_response
    response = response.render()
               ^^^^^^^^^^^^^^^^^
  File "/home/work/learning/tasks/book_app2/.venv/lib/python3.12/site-packages/django/template/response.py", line 114, in render
    self.content = self.rendered_content
                   ^^^^^^^^^^^^^^^^^^^^^
  File "/home/work/learning/tasks/book_app2/.venv/lib/python3.12/site-packages/rest_framework/response.py", line 74, in rendered_content
    ret = renderer.render(self.data, accepted_media_type, context)
          ^^^^^^^^^^^^^^^^^^^^^^^^^^^^^^^^^^^^^^^^^^^^^^^^^^^^^^^^
  File "/home/work/learning/tasks/book_app2/.venv/lib/python3.12/site-packages/rest_framework/renderers.py", line 99, in render
    ret = json.dumps(
          ^^^^^^^^^^^
  File "/home/work/learning/tasks/book_app2/.venv/lib/python3.12/site-packages/rest_framework/utils/json.py", line 25, in dumps
    return json.dumps(*args, **kwargs)
           ^^^^^^^^^^^^^^^^^^^^^^^^^^^
  File "/usr/lib/python3.12/json/__init__.py", line 238, in dumps
    **kw).encode(obj)
          ^^^^^^^^^^^
  File "/usr/lib/python3.12/json/encoder.py", line 200, in encode
    chunks = self.iterencode(o, _one_shot=True)
             ^^^^^^^^^^^^^^^^^^^^^^^^^^^^^^^^^^
  File "/usr/lib/python3.12/json/encoder.py", line 258, in iterencode
    return _iterencode(o, 0)
           ^^^^^^^^^^^^^^^^^
  File "/home/work/learning/tasks/book_app2/.venv/lib/python3.12/site-packages/rest_framework/utils/encoders.py", line 67, in default
    return super().default(obj)
           ^^^^^^^^^^^^^^^^^^^^
  File "/usr/lib/python3.12/json/encoder.py", line 180, in default
    raise TypeError(f'Object of type {o.__class__.__name__} '
TypeError: Object of type DoesNotExist is not JSON serializable
INFO:django.utils.autoreload:/home/work/learning/tasks/book_app2/books/services/book_service.py changed, reloading.
ERROR:books.helpers.logging_helper:BookDetailView get :: exception :: Book matching query does not exist.
ERROR:django.request:Internal Server Error: /api/v1/books/3c4b725d-55cf-4dcc-a83c-e35c83655484/
Traceback (most recent call last):
  File "/home/work/learning/tasks/book_app2/.venv/lib/python3.12/site-packages/django/core/handlers/exception.py", line 55, in inner
    response = get_response(request)
               ^^^^^^^^^^^^^^^^^^^^^
  File "/home/work/learning/tasks/book_app2/.venv/lib/python3.12/site-packages/django/core/handlers/base.py", line 220, in _get_response
    response = response.render()
               ^^^^^^^^^^^^^^^^^
  File "/home/work/learning/tasks/book_app2/.venv/lib/python3.12/site-packages/django/template/response.py", line 114, in render
    self.content = self.rendered_content
                   ^^^^^^^^^^^^^^^^^^^^^
  File "/home/work/learning/tasks/book_app2/.venv/lib/python3.12/site-packages/rest_framework/response.py", line 74, in rendered_content
    ret = renderer.render(self.data, accepted_media_type, context)
          ^^^^^^^^^^^^^^^^^^^^^^^^^^^^^^^^^^^^^^^^^^^^^^^^^^^^^^^^
  File "/home/work/learning/tasks/book_app2/.venv/lib/python3.12/site-packages/rest_framework/renderers.py", line 99, in render
    ret = json.dumps(
          ^^^^^^^^^^^
  File "/home/work/learning/tasks/book_app2/.venv/lib/python3.12/site-packages/rest_framework/utils/json.py", line 25, in dumps
    return json.dumps(*args, **kwargs)
           ^^^^^^^^^^^^^^^^^^^^^^^^^^^
  File "/usr/lib/python3.12/json/__init__.py", line 238, in dumps
    **kw).encode(obj)
          ^^^^^^^^^^^
  File "/usr/lib/python3.12/json/encoder.py", line 200, in encode
    chunks = self.iterencode(o, _one_shot=True)
             ^^^^^^^^^^^^^^^^^^^^^^^^^^^^^^^^^^
  File "/usr/lib/python3.12/json/encoder.py", line 258, in iterencode
    return _iterencode(o, 0)
           ^^^^^^^^^^^^^^^^^
  File "/home/work/learning/tasks/book_app2/.venv/lib/python3.12/site-packages/rest_framework/utils/encoders.py", line 67, in default
    return super().default(obj)
           ^^^^^^^^^^^^^^^^^^^^
  File "/usr/lib/python3.12/json/encoder.py", line 180, in default
    raise TypeError(f'Object of type {o.__class__.__name__} '
TypeError: Object of type DoesNotExist is not JSON serializable
INFO:django.utils.autoreload:/home/work/learning/tasks/book_app2/books/services/book_service.py changed, reloading.
INFO:django.utils.autoreload:/home/work/learning/tasks/book_app2/books/views/book_api.py changed, reloading.
ERROR:books.helpers.logging_helper:BookDetailView get :: exception :: Book matching query does not exist.
ERROR:django.request:Internal Server Error: /api/v1/books/3c4b725d-55cf-4dcc-a83c-e35c83655484/
Traceback (most recent call last):
  File "/home/work/learning/tasks/book_app2/.venv/lib/python3.12/site-packages/django/core/handlers/exception.py", line 55, in inner
    response = get_response(request)
               ^^^^^^^^^^^^^^^^^^^^^
  File "/home/work/learning/tasks/book_app2/.venv/lib/python3.12/site-packages/django/core/handlers/base.py", line 220, in _get_response
    response = response.render()
               ^^^^^^^^^^^^^^^^^
  File "/home/work/learning/tasks/book_app2/.venv/lib/python3.12/site-packages/django/template/response.py", line 114, in render
    self.content = self.rendered_content
                   ^^^^^^^^^^^^^^^^^^^^^
  File "/home/work/learning/tasks/book_app2/.venv/lib/python3.12/site-packages/rest_framework/response.py", line 74, in rendered_content
    ret = renderer.render(self.data, accepted_media_type, context)
          ^^^^^^^^^^^^^^^^^^^^^^^^^^^^^^^^^^^^^^^^^^^^^^^^^^^^^^^^
  File "/home/work/learning/tasks/book_app2/.venv/lib/python3.12/site-packages/rest_framework/renderers.py", line 99, in render
    ret = json.dumps(
          ^^^^^^^^^^^
  File "/home/work/learning/tasks/book_app2/.venv/lib/python3.12/site-packages/rest_framework/utils/json.py", line 25, in dumps
    return json.dumps(*args, **kwargs)
           ^^^^^^^^^^^^^^^^^^^^^^^^^^^
  File "/usr/lib/python3.12/json/__init__.py", line 238, in dumps
    **kw).encode(obj)
          ^^^^^^^^^^^
  File "/usr/lib/python3.12/json/encoder.py", line 200, in encode
    chunks = self.iterencode(o, _one_shot=True)
             ^^^^^^^^^^^^^^^^^^^^^^^^^^^^^^^^^^
  File "/usr/lib/python3.12/json/encoder.py", line 258, in iterencode
    return _iterencode(o, 0)
           ^^^^^^^^^^^^^^^^^
  File "/home/work/learning/tasks/book_app2/.venv/lib/python3.12/site-packages/rest_framework/utils/encoders.py", line 67, in default
    return super().default(obj)
           ^^^^^^^^^^^^^^^^^^^^
  File "/usr/lib/python3.12/json/encoder.py", line 180, in default
    raise TypeError(f'Object of type {o.__class__.__name__} '
TypeError: Object of type DoesNotExist is not JSON serializable
INFO:django.utils.autoreload:/home/work/learning/tasks/book_app2/books/views/book_api.py changed, reloading.
INFO:django.utils.autoreload:/home/work/learning/tasks/book_app2/books/views/book_api.py changed, reloading.
INFO:django.utils.autoreload:/home/work/learning/tasks/book_app2/books/views/book_api.py changed, reloading.
ERROR:books.helpers.logging_helper:BookDetailView get :: exception :: Book matching query does not exist.
ERROR:django.request:Internal Server Error: /api/v1/books/3c4b725d-55cf-4dcc-a83c-e35c83655484/
Traceback (most recent call last):
  File "/home/work/learning/tasks/book_app2/.venv/lib/python3.12/site-packages/django/core/handlers/exception.py", line 55, in inner
    response = get_response(request)
               ^^^^^^^^^^^^^^^^^^^^^
  File "/home/work/learning/tasks/book_app2/.venv/lib/python3.12/site-packages/django/core/handlers/base.py", line 220, in _get_response
    response = response.render()
               ^^^^^^^^^^^^^^^^^
  File "/home/work/learning/tasks/book_app2/.venv/lib/python3.12/site-packages/django/template/response.py", line 114, in render
    self.content = self.rendered_content
                   ^^^^^^^^^^^^^^^^^^^^^
  File "/home/work/learning/tasks/book_app2/.venv/lib/python3.12/site-packages/rest_framework/response.py", line 74, in rendered_content
    ret = renderer.render(self.data, accepted_media_type, context)
          ^^^^^^^^^^^^^^^^^^^^^^^^^^^^^^^^^^^^^^^^^^^^^^^^^^^^^^^^
  File "/home/work/learning/tasks/book_app2/.venv/lib/python3.12/site-packages/rest_framework/renderers.py", line 99, in render
    ret = json.dumps(
          ^^^^^^^^^^^
  File "/home/work/learning/tasks/book_app2/.venv/lib/python3.12/site-packages/rest_framework/utils/json.py", line 25, in dumps
    return json.dumps(*args, **kwargs)
           ^^^^^^^^^^^^^^^^^^^^^^^^^^^
  File "/usr/lib/python3.12/json/__init__.py", line 238, in dumps
    **kw).encode(obj)
          ^^^^^^^^^^^
  File "/usr/lib/python3.12/json/encoder.py", line 200, in encode
    chunks = self.iterencode(o, _one_shot=True)
             ^^^^^^^^^^^^^^^^^^^^^^^^^^^^^^^^^^
  File "/usr/lib/python3.12/json/encoder.py", line 258, in iterencode
    return _iterencode(o, 0)
           ^^^^^^^^^^^^^^^^^
  File "/home/work/learning/tasks/book_app2/.venv/lib/python3.12/site-packages/rest_framework/utils/encoders.py", line 67, in default
    return super().default(obj)
           ^^^^^^^^^^^^^^^^^^^^
  File "/usr/lib/python3.12/json/encoder.py", line 180, in default
    raise TypeError(f'Object of type {o.__class__.__name__} '
TypeError: Object of type DoesNotExist is not JSON serializable
INFO:django.utils.autoreload:/home/work/learning/tasks/book_app2/books/views/book_api.py changed, reloading.
ERROR:books.helpers.logging_helper:BookDetailView get :: exception :: Book matching query does not exist.
ERROR:django.request:Internal Server Error: /api/v1/books/3c4b725d-55cf-4dcc-a83c-e35c83655484/
Traceback (most recent call last):
  File "/home/work/learning/tasks/book_app2/.venv/lib/python3.12/site-packages/django/core/handlers/exception.py", line 55, in inner
    response = get_response(request)
               ^^^^^^^^^^^^^^^^^^^^^
  File "/home/work/learning/tasks/book_app2/.venv/lib/python3.12/site-packages/django/core/handlers/base.py", line 220, in _get_response
    response = response.render()
               ^^^^^^^^^^^^^^^^^
  File "/home/work/learning/tasks/book_app2/.venv/lib/python3.12/site-packages/django/template/response.py", line 114, in render
    self.content = self.rendered_content
                   ^^^^^^^^^^^^^^^^^^^^^
  File "/home/work/learning/tasks/book_app2/.venv/lib/python3.12/site-packages/rest_framework/response.py", line 74, in rendered_content
    ret = renderer.render(self.data, accepted_media_type, context)
          ^^^^^^^^^^^^^^^^^^^^^^^^^^^^^^^^^^^^^^^^^^^^^^^^^^^^^^^^
  File "/home/work/learning/tasks/book_app2/.venv/lib/python3.12/site-packages/rest_framework/renderers.py", line 99, in render
    ret = json.dumps(
          ^^^^^^^^^^^
  File "/home/work/learning/tasks/book_app2/.venv/lib/python3.12/site-packages/rest_framework/utils/json.py", line 25, in dumps
    return json.dumps(*args, **kwargs)
           ^^^^^^^^^^^^^^^^^^^^^^^^^^^
  File "/usr/lib/python3.12/json/__init__.py", line 238, in dumps
    **kw).encode(obj)
          ^^^^^^^^^^^
  File "/usr/lib/python3.12/json/encoder.py", line 200, in encode
    chunks = self.iterencode(o, _one_shot=True)
             ^^^^^^^^^^^^^^^^^^^^^^^^^^^^^^^^^^
  File "/usr/lib/python3.12/json/encoder.py", line 258, in iterencode
    return _iterencode(o, 0)
           ^^^^^^^^^^^^^^^^^
  File "/home/work/learning/tasks/book_app2/.venv/lib/python3.12/site-packages/rest_framework/utils/encoders.py", line 67, in default
    return super().default(obj)
           ^^^^^^^^^^^^^^^^^^^^
  File "/usr/lib/python3.12/json/encoder.py", line 180, in default
    raise TypeError(f'Object of type {o.__class__.__name__} '
TypeError: Object of type DoesNotExist is not JSON serializable
INFO:django.utils.autoreload:/home/work/learning/tasks/book_app2/books/views/book_api.py changed, reloading.
INFO:django.utils.autoreload:/home/work/learning/tasks/book_app2/books/views/book_api.py changed, reloading.
ERROR:books.helpers.logging_helper:BookDetailView get :: exception :: Book matching query does not exist.
WARNING:django.request:Bad Request: /api/v1/books/3c4b725d-55cf-4dcc-a83c-e35c83655484/
INFO:django.utils.autoreload:/home/work/learning/tasks/book_app2/books/views/book_api.py changed, reloading.
ERROR:books.helpers.logging_helper:BookDetailView get :: exception :: Book matching query does not exist.
ERROR:django.request:Internal Server Error: /api/v1/books/3c4b725d-55cf-4dcc-a83c-e35c83655484/
Traceback (most recent call last):
  File "/home/work/learning/tasks/book_app2/.venv/lib/python3.12/site-packages/django/core/handlers/exception.py", line 55, in inner
    response = get_response(request)
               ^^^^^^^^^^^^^^^^^^^^^
  File "/home/work/learning/tasks/book_app2/.venv/lib/python3.12/site-packages/django/core/handlers/base.py", line 220, in _get_response
    response = response.render()
               ^^^^^^^^^^^^^^^^^
  File "/home/work/learning/tasks/book_app2/.venv/lib/python3.12/site-packages/django/template/response.py", line 114, in render
    self.content = self.rendered_content
                   ^^^^^^^^^^^^^^^^^^^^^
  File "/home/work/learning/tasks/book_app2/.venv/lib/python3.12/site-packages/rest_framework/response.py", line 74, in rendered_content
    ret = renderer.render(self.data, accepted_media_type, context)
          ^^^^^^^^^^^^^^^^^^^^^^^^^^^^^^^^^^^^^^^^^^^^^^^^^^^^^^^^
  File "/home/work/learning/tasks/book_app2/.venv/lib/python3.12/site-packages/rest_framework/renderers.py", line 99, in render
    ret = json.dumps(
          ^^^^^^^^^^^
  File "/home/work/learning/tasks/book_app2/.venv/lib/python3.12/site-packages/rest_framework/utils/json.py", line 25, in dumps
    return json.dumps(*args, **kwargs)
           ^^^^^^^^^^^^^^^^^^^^^^^^^^^
  File "/usr/lib/python3.12/json/__init__.py", line 238, in dumps
    **kw).encode(obj)
          ^^^^^^^^^^^
  File "/usr/lib/python3.12/json/encoder.py", line 200, in encode
    chunks = self.iterencode(o, _one_shot=True)
             ^^^^^^^^^^^^^^^^^^^^^^^^^^^^^^^^^^
  File "/usr/lib/python3.12/json/encoder.py", line 258, in iterencode
    return _iterencode(o, 0)
           ^^^^^^^^^^^^^^^^^
  File "/home/work/learning/tasks/book_app2/.venv/lib/python3.12/site-packages/rest_framework/utils/encoders.py", line 67, in default
    return super().default(obj)
           ^^^^^^^^^^^^^^^^^^^^
  File "/usr/lib/python3.12/json/encoder.py", line 180, in default
    raise TypeError(f'Object of type {o.__class__.__name__} '
TypeError: Object of type DoesNotExist is not JSON serializable
INFO:django.utils.autoreload:/home/work/learning/tasks/book_app2/books/views/book_api.py changed, reloading.
ERROR:books.helpers.logging_helper:BookDetailView get :: exception :: Book matching query does not exist.
WARNING:django.request:Bad Request: /api/v1/books/3c4b725d-55cf-4dcc-a83c-e35c83655484/
ERROR:books.helpers.logging_helper:BookDetailView get :: exception :: Book matching query does not exist.
WARNING:django.request:Bad Request: /api/v1/books/3c4b725d-55cf-4dcc-a83c-e35c83655484/
ERROR:books.helpers.logging_helper:BookDetailView get :: exception :: Book matching query does not exist.
WARNING:django.request:Bad Request: /api/v1/books/3c4b725d-55cf-4dcc-a83c-e35c83655484/
ERROR:books.helpers.logging_helper:BookDetailView get :: exception :: Book matching query does not exist.
WARNING:django.request:Bad Request: /api/v1/books/3c4b725d-55cf-4dcc-a83c-e35c83655484/
INFO:django.utils.autoreload:/home/work/learning/tasks/book_app2/books/views/book_api.py changed, reloading.
INFO:django.utils.autoreload:/home/work/learning/tasks/book_app2/books/views/book_api.py changed, reloading.
ERROR:books.helpers.logging_helper:BookDetailView get :: exception :: Book matching query does not exist.
WARNING:django.request:Bad Request: /api/v1/books/3c4b725d-55cf-4dcc-a83c-e35c83655484/
INFO:django.utils.autoreload:/home/work/learning/tasks/book_app2/books/views/book_api.py changed, reloading.
ERROR:books.helpers.logging_helper:BookDetailView get :: exception :: Book matching query does not exist.
WARNING:django.request:Bad Request: /api/v1/books/3c4b725d-55cf-4dcc-a83c-e35c83655484/
INFO:django.utils.autoreload:/home/work/learning/tasks/book_app2/books/views/book_api.py changed, reloading.
INFO:django.utils.autoreload:/home/work/learning/tasks/book_app2/books/views/book_api.py changed, reloading.
INFO:django.utils.autoreload:/home/work/learning/tasks/book_app2/books/views/book_api.py changed, reloading.
WARNING:django.request:Method Not Allowed: /api/v1/books/
INFO:django.utils.autoreload:/home/work/learning/tasks/book_app2/books/views/book_api.py changed, reloading.
INFO:django.utils.autoreload:/home/work/learning/tasks/book_app2/books/views/book_api.py changed, reloading.
INFO:django.utils.autoreload:/home/work/learning/tasks/book_app2/books/views/book_api.py changed, reloading.
INFO:django.utils.autoreload:/home/work/learning/tasks/book_app2/books/services/book_service.py changed, reloading.
INFO:django.utils.autoreload:/home/work/learning/tasks/book_app2/books/services/book_service.py changed, reloading.
INFO:django.utils.autoreload:/home/work/learning/tasks/book_app2/books/services/book_service.py changed, reloading.
INFO:django.utils.autoreload:/home/work/learning/tasks/book_app2/books/views/book_api.py changed, reloading.
INFO:django.utils.autoreload:/home/work/learning/tasks/book_app2/books/views/book_api.py changed, reloading.
INFO:django.utils.autoreload:/home/work/learning/tasks/book_app2/books/services/book_service.py changed, reloading.
INFO:django.utils.autoreload:/home/work/learning/tasks/book_app2/books/services/book_service.py changed, reloading.
INFO:django.utils.autoreload:/home/work/learning/tasks/book_app2/books/services/book_service.py changed, reloading.
INFO:django.utils.autoreload:/home/work/learning/tasks/book_app2/books/services/book_service.py changed, reloading.
INFO:django.utils.autoreload:/home/work/learning/tasks/book_app2/books/views/book_api.py changed, reloading.
INFO:django.utils.autoreload:/home/work/learning/tasks/book_app2/books/views/book_api.py changed, reloading.
INFO:django.utils.autoreload:/home/work/learning/tasks/book_app2/books/views/book_api.py changed, reloading.
INFO:django.utils.autoreload:/home/work/learning/tasks/book_app2/books/views/book_api.py changed, reloading.
INFO:django.utils.autoreload:/home/work/learning/tasks/book_app2/books/views/book_api.py changed, reloading.
INFO:django.utils.autoreload:/home/work/learning/tasks/book_app2/books/views/book_api.py changed, reloading.
INFO:django.utils.autoreload:/home/work/learning/tasks/book_app2/books/views/book_api.py changed, reloading.
WARNING:django.request:Method Not Allowed: /api/v1/books/
ERROR:django.request:Internal Server Error: /api/v1/books/
Traceback (most recent call last):
  File "/home/work/learning/tasks/book_app2/.venv/lib/python3.12/site-packages/django/core/handlers/exception.py", line 55, in inner
    response = get_response(request)
               ^^^^^^^^^^^^^^^^^^^^^
  File "/home/work/learning/tasks/book_app2/.venv/lib/python3.12/site-packages/django/core/handlers/base.py", line 197, in _get_response
    response = wrapped_callback(request, *callback_args, **callback_kwargs)
               ^^^^^^^^^^^^^^^^^^^^^^^^^^^^^^^^^^^^^^^^^^^^^^^^^^^^^^^^^^^^
  File "/home/work/learning/tasks/book_app2/.venv/lib/python3.12/site-packages/django/views/decorators/csrf.py", line 65, in _view_wrapper
    return view_func(request, *args, **kwargs)
           ^^^^^^^^^^^^^^^^^^^^^^^^^^^^^^^^^^^
  File "/home/work/learning/tasks/book_app2/.venv/lib/python3.12/site-packages/django/views/generic/base.py", line 104, in view
    return self.dispatch(request, *args, **kwargs)
           ^^^^^^^^^^^^^^^^^^^^^^^^^^^^^^^^^^^^^^^
  File "/home/work/learning/tasks/book_app2/.venv/lib/python3.12/site-packages/rest_framework/views.py", line 509, in dispatch
    response = self.handle_exception(exc)
               ^^^^^^^^^^^^^^^^^^^^^^^^^^
  File "/home/work/learning/tasks/book_app2/.venv/lib/python3.12/site-packages/rest_framework/views.py", line 469, in handle_exception
    self.raise_uncaught_exception(exc)
  File "/home/work/learning/tasks/book_app2/.venv/lib/python3.12/site-packages/rest_framework/views.py", line 480, in raise_uncaught_exception
    raise exc
  File "/home/work/learning/tasks/book_app2/.venv/lib/python3.12/site-packages/rest_framework/views.py", line 506, in dispatch
    response = handler(request, *args, **kwargs)
               ^^^^^^^^^^^^^^^^^^^^^^^^^^^^^^^^^
  File "/home/work/learning/tasks/book_app2/.venv/lib/python3.12/site-packages/rest_framework/decorators.py", line 50, in handler
    return func(*args, **kwargs)
           ^^^^^^^^^^^^^^^^^^^^^
  File "/home/work/learning/tasks/book_app2/books/views/book_api.py", line 23, in book_list
    book, is_book_created = book_service.create_new_book(request.data)
                            ^^^^^^^^^^^^^^^^^^^^^^^^^^^^^^^^^^^^^^^^^^
  File "/home/work/learning/tasks/book_app2/books/services/book_service.py", line 33, in create_new_book
    if serializer.is_valid():
       ^^^^^^^^^^^^^^^^^^^^^
  File "/home/work/learning/tasks/book_app2/.venv/lib/python3.12/site-packages/rest_framework/serializers.py", line 216, in is_valid
    assert hasattr(self, 'initial_data'), (
           ^^^^^^^^^^^^^^^^^^^^^^^^^^^^^
AssertionError: Cannot call `.is_valid()` as no `data=` keyword argument was passed when instantiating the serializer instance.
INFO:django.utils.autoreload:/home/work/learning/tasks/book_app2/books/views/book_api.py changed, reloading.
INFO:django.utils.autoreload:/home/work/learning/tasks/book_app2/books/services/book_service.py changed, reloading.
INFO:django.utils.autoreload:/home/work/learning/tasks/book_app2/books/services/book_service.py changed, reloading.
ERROR:books.helpers.logging_helper:BookService.create_new_book :: ValueError :: {'content': [ErrorDetail(string='This field is required.', code='required')], 'owner': [ErrorDetail(string='This field is required.', code='required')], 'image': [ErrorDetail(string='No file was submitted.', code='required')]}
INFO:django.utils.autoreload:/home/work/learning/tasks/book_app2/books/services/book_service.py changed, reloading.
ERROR:books.helpers.logging_helper:BookService.create_new_book :: ValueError :: {'content': [ErrorDetail(string='This field is required.', code='required')], 'owner': [ErrorDetail(string='This field is required.', code='required')], 'image': [ErrorDetail(string='No file was submitted.', code='required')]}
ERROR:books.helpers.logging_helper:BookService.create_new_book :: ValueError :: {'content': [ErrorDetail(string='This field is required.', code='required')], 'owner': [ErrorDetail(string='This field is required.', code='required')], 'image': [ErrorDetail(string='No file was submitted.', code='required')]}
ERROR:books.helpers.logging_helper:BookService.create_new_book :: ValueError :: {'title': [ErrorDetail(string='This field is required.', code='required')], 'content': [ErrorDetail(string='This field is required.', code='required')], 'owner': [ErrorDetail(string='This field is required.', code='required')], 'image': [ErrorDetail(string='No file was submitted.', code='required')]}
DEBUG:PIL.PngImagePlugin:STREAM b'IHDR' 16 13
DEBUG:PIL.PngImagePlugin:STREAM b'sBIT' 41 4
DEBUG:PIL.PngImagePlugin:b'sBIT' 41 4 (unknown)
DEBUG:PIL.PngImagePlugin:STREAM b'tEXt' 57 25
DEBUG:PIL.PngImagePlugin:STREAM b'tEXt' 94 47
DEBUG:PIL.PngImagePlugin:STREAM b'IDAT' 153 7808
DEBUG:PIL.Image:Importing BlpImagePlugin
DEBUG:PIL.Image:Importing BmpImagePlugin
DEBUG:PIL.Image:Importing BufrStubImagePlugin
DEBUG:PIL.Image:Importing CurImagePlugin
DEBUG:PIL.Image:Importing DcxImagePlugin
DEBUG:PIL.Image:Importing DdsImagePlugin
DEBUG:PIL.Image:Importing EpsImagePlugin
DEBUG:PIL.Image:Importing FitsImagePlugin
DEBUG:PIL.Image:Importing FliImagePlugin
DEBUG:PIL.Image:Importing FpxImagePlugin
DEBUG:PIL.Image:Image: failed to import FpxImagePlugin: No module named 'olefile'
DEBUG:PIL.Image:Importing FtexImagePlugin
DEBUG:PIL.Image:Importing GbrImagePlugin
DEBUG:PIL.Image:Importing GifImagePlugin
DEBUG:PIL.Image:Importing GribStubImagePlugin
DEBUG:PIL.Image:Importing Hdf5StubImagePlugin
DEBUG:PIL.Image:Importing IcnsImagePlugin
DEBUG:PIL.Image:Importing IcoImagePlugin
DEBUG:PIL.Image:Importing ImImagePlugin
DEBUG:PIL.Image:Importing ImtImagePlugin
DEBUG:PIL.Image:Importing IptcImagePlugin
DEBUG:PIL.Image:Importing JpegImagePlugin
DEBUG:PIL.Image:Importing Jpeg2KImagePlugin
DEBUG:PIL.Image:Importing McIdasImagePlugin
DEBUG:PIL.Image:Importing MicImagePlugin
DEBUG:PIL.Image:Image: failed to import MicImagePlugin: No module named 'olefile'
DEBUG:PIL.Image:Importing MpegImagePlugin
DEBUG:PIL.Image:Importing MpoImagePlugin
DEBUG:PIL.Image:Importing MspImagePlugin
DEBUG:PIL.Image:Importing PalmImagePlugin
DEBUG:PIL.Image:Importing PcdImagePlugin
DEBUG:PIL.Image:Importing PcxImagePlugin
DEBUG:PIL.Image:Importing PdfImagePlugin
DEBUG:PIL.Image:Importing PixarImagePlugin
DEBUG:PIL.Image:Importing PngImagePlugin
DEBUG:PIL.Image:Importing PpmImagePlugin
DEBUG:PIL.Image:Importing PsdImagePlugin
DEBUG:PIL.Image:Importing QoiImagePlugin
DEBUG:PIL.Image:Importing SgiImagePlugin
DEBUG:PIL.Image:Importing SpiderImagePlugin
DEBUG:PIL.Image:Importing SunImagePlugin
DEBUG:PIL.Image:Importing TgaImagePlugin
DEBUG:PIL.Image:Importing TiffImagePlugin
DEBUG:PIL.Image:Importing WebPImagePlugin
DEBUG:PIL.Image:Importing WmfImagePlugin
DEBUG:PIL.Image:Importing XbmImagePlugin
DEBUG:PIL.Image:Importing XpmImagePlugin
DEBUG:PIL.Image:Importing XVThumbImagePlugin
INFO:books.helpers.logging_helper:New book created
INFO:django.utils.autoreload:/home/work/learning/tasks/book_app2/books/services/book_service.py changed, reloading.
DEBUG:PIL.PngImagePlugin:STREAM b'IHDR' 16 13
DEBUG:PIL.PngImagePlugin:STREAM b'sBIT' 41 4
DEBUG:PIL.PngImagePlugin:b'sBIT' 41 4 (unknown)
DEBUG:PIL.PngImagePlugin:STREAM b'tEXt' 57 25
DEBUG:PIL.PngImagePlugin:STREAM b'tEXt' 94 47
DEBUG:PIL.PngImagePlugin:STREAM b'IDAT' 153 7808
DEBUG:PIL.Image:Importing BlpImagePlugin
DEBUG:PIL.Image:Importing BmpImagePlugin
DEBUG:PIL.Image:Importing BufrStubImagePlugin
DEBUG:PIL.Image:Importing CurImagePlugin
DEBUG:PIL.Image:Importing DcxImagePlugin
DEBUG:PIL.Image:Importing DdsImagePlugin
DEBUG:PIL.Image:Importing EpsImagePlugin
DEBUG:PIL.Image:Importing FitsImagePlugin
DEBUG:PIL.Image:Importing FliImagePlugin
DEBUG:PIL.Image:Importing FpxImagePlugin
DEBUG:PIL.Image:Image: failed to import FpxImagePlugin: No module named 'olefile'
DEBUG:PIL.Image:Importing FtexImagePlugin
DEBUG:PIL.Image:Importing GbrImagePlugin
DEBUG:PIL.Image:Importing GifImagePlugin
DEBUG:PIL.Image:Importing GribStubImagePlugin
DEBUG:PIL.Image:Importing Hdf5StubImagePlugin
DEBUG:PIL.Image:Importing IcnsImagePlugin
DEBUG:PIL.Image:Importing IcoImagePlugin
DEBUG:PIL.Image:Importing ImImagePlugin
DEBUG:PIL.Image:Importing ImtImagePlugin
DEBUG:PIL.Image:Importing IptcImagePlugin
DEBUG:PIL.Image:Importing JpegImagePlugin
DEBUG:PIL.Image:Importing Jpeg2KImagePlugin
DEBUG:PIL.Image:Importing McIdasImagePlugin
DEBUG:PIL.Image:Importing MicImagePlugin
DEBUG:PIL.Image:Image: failed to import MicImagePlugin: No module named 'olefile'
DEBUG:PIL.Image:Importing MpegImagePlugin
DEBUG:PIL.Image:Importing MpoImagePlugin
DEBUG:PIL.Image:Importing MspImagePlugin
DEBUG:PIL.Image:Importing PalmImagePlugin
DEBUG:PIL.Image:Importing PcdImagePlugin
DEBUG:PIL.Image:Importing PcxImagePlugin
DEBUG:PIL.Image:Importing PdfImagePlugin
DEBUG:PIL.Image:Importing PixarImagePlugin
DEBUG:PIL.Image:Importing PngImagePlugin
DEBUG:PIL.Image:Importing PpmImagePlugin
DEBUG:PIL.Image:Importing PsdImagePlugin
DEBUG:PIL.Image:Importing QoiImagePlugin
DEBUG:PIL.Image:Importing SgiImagePlugin
DEBUG:PIL.Image:Importing SpiderImagePlugin
DEBUG:PIL.Image:Importing SunImagePlugin
DEBUG:PIL.Image:Importing TgaImagePlugin
DEBUG:PIL.Image:Importing TiffImagePlugin
DEBUG:PIL.Image:Importing WebPImagePlugin
DEBUG:PIL.Image:Importing WmfImagePlugin
DEBUG:PIL.Image:Importing XbmImagePlugin
DEBUG:PIL.Image:Importing XpmImagePlugin
DEBUG:PIL.Image:Importing XVThumbImagePlugin
INFO:books.helpers.logging_helper:New book created
DEBUG:PIL.PngImagePlugin:STREAM b'IHDR' 16 13
DEBUG:PIL.PngImagePlugin:STREAM b'sBIT' 41 4
DEBUG:PIL.PngImagePlugin:b'sBIT' 41 4 (unknown)
DEBUG:PIL.PngImagePlugin:STREAM b'tEXt' 57 25
DEBUG:PIL.PngImagePlugin:STREAM b'tEXt' 94 47
DEBUG:PIL.PngImagePlugin:STREAM b'IDAT' 153 7808
INFO:books.helpers.logging_helper:New book created
DEBUG:PIL.PngImagePlugin:STREAM b'IHDR' 16 13
DEBUG:PIL.PngImagePlugin:STREAM b'sBIT' 41 4
DEBUG:PIL.PngImagePlugin:b'sBIT' 41 4 (unknown)
DEBUG:PIL.PngImagePlugin:STREAM b'tEXt' 57 25
DEBUG:PIL.PngImagePlugin:STREAM b'tEXt' 94 47
DEBUG:PIL.PngImagePlugin:STREAM b'IDAT' 153 7808
INFO:books.helpers.logging_helper:New book created
ERROR:books.helpers.logging_helper:BookDetailView get :: exception :: Book matching query does not exist.
WARNING:django.request:Bad Request: /api/v1/books/3c4b725d-55cf-4dcc-a83c-e35c83655484/
INFO:django.utils.autoreload:/home/work/learning/tasks/book_app2/books/services/book_service.py changed, reloading.
INFO:django.utils.autoreload:/home/work/learning/tasks/book_app2/books/services/book_service.py changed, reloading.
INFO:django.utils.autoreload:/home/work/learning/tasks/book_app2/books/views/book_api.py changed, reloading.
INFO:django.utils.autoreload:/home/work/learning/tasks/book_app2/books/models/book.py changed, reloading.
INFO:django.utils.autoreload:/home/work/learning/tasks/book_app2/books/models/book.py changed, reloading.
INFO:django.utils.autoreload:/home/work/learning/tasks/book_app2/books/serializers/book_serializer.py changed, reloading.
ERROR:books.helpers.logging_helper:BookView get :: exception::  Book.get_all_books() takes 1 positional argument but 2 were given
WARNING:django.request:Bad Request: /api/v1/books/
INFO:django.utils.autoreload:/home/work/learning/tasks/book_app2/books/serializers/book_serializer.py changed, reloading.
ERROR:books.helpers.logging_helper:BookView get :: exception::  Book.get_all_books() takes 1 positional argument but 2 were given
WARNING:django.request:Bad Request: /api/v1/books/
ERROR:books.helpers.logging_helper:BookView get :: exception::  Book.get_all_books() takes 1 positional argument but 2 were given
WARNING:django.request:Bad Request: /api/v1/books/
INFO:django.utils.autoreload:/home/work/learning/tasks/book_app2/books/models/book.py changed, reloading.
INFO:django.utils.autoreload:/home/work/learning/tasks/book_app2/books/serializers/book_serializer.py changed, reloading.
INFO:django.utils.autoreload:/home/work/learning/tasks/book_app2/books/serializers/book_serializer.py changed, reloading.
INFO:django.utils.autoreload:/home/work/learning/tasks/book_app2/books/serializers/book_serializer.py changed, reloading.
ERROR:books.helpers.logging_helper:BookView get :: exception::  Got AttributeError when attempting to get a value for field `average_rating` on serializer `BookSerializer`.
The serializer field might be named incorrectly and not match any attribute or key on the `Book` instance.
Original exception text was: 'Book' object has no attribute 'reviews'.
WARNING:django.request:Bad Request: /api/v1/books/
INFO:django.utils.autoreload:/home/work/learning/tasks/book_app2/books/serializers/book_serializer.py changed, reloading.
ERROR:books.helpers.logging_helper:BookView get :: exception::  Got AttributeError when attempting to get a value for field `average_rating` on serializer `BookSerializer`.
The serializer field might be named incorrectly and not match any attribute or key on the `Book` instance.
Original exception text was: 'Book' object has no attribute 'reviews'.
WARNING:django.request:Bad Request: /api/v1/books/
ERROR:books.helpers.logging_helper:BookView get :: exception::  Got AttributeError when attempting to get a value for field `average_rating` on serializer `BookSerializer`.
The serializer field might be named incorrectly and not match any attribute or key on the `Book` instance.
Original exception text was: 'Book' object has no attribute 'reviews'.
WARNING:django.request:Bad Request: /api/v1/books/
INFO:django.utils.autoreload:/home/work/learning/tasks/book_app2/books/serializers/book_serializer.py changed, reloading.
INFO:django.utils.autoreload:/home/work/learning/tasks/book_app2/books/serializers/book_serializer.py changed, reloading.
INFO:django.utils.autoreload:/home/work/learning/tasks/book_app2/books/serializers/book_serializer.py changed, reloading.
ERROR:books.helpers.logging_helper:BookView get :: exception::  Got AttributeError when attempting to get a value for field `average_rating` on serializer `BookSerializer`.
The serializer field might be named incorrectly and not match any attribute or key on the `Book` instance.
Original exception text was: 'Book' object has no attribute 'reviews'.
WARNING:django.request:Bad Request: /api/v1/books/
ERROR:books.helpers.logging_helper:BookView get :: exception::  Got AttributeError when attempting to get a value for field `average_rating` on serializer `BookSerializer`.
The serializer field might be named incorrectly and not match any attribute or key on the `Book` instance.
Original exception text was: 'Book' object has no attribute 'reviews'.
WARNING:django.request:Bad Request: /api/v1/books/
INFO:django.utils.autoreload:/home/work/learning/tasks/book_app2/books/serializers/book_serializer.py changed, reloading.
ERROR:books.helpers.logging_helper:BookView get :: exception::  Field name `__all__` is not valid for model `Book` in `books.serializers.book_serializer.BookSerializer`.
WARNING:django.request:Bad Request: /api/v1/books/
INFO:django.utils.autoreload:/home/work/learning/tasks/book_app2/books/serializers/book_serializer.py changed, reloading.
INFO:django.utils.autoreload:/home/work/learning/tasks/book_app2/books/serializers/book_serializer.py changed, reloading.
ERROR:books.helpers.logging_helper:BookView get :: exception::  Got AttributeError when attempting to get a value for field `average_rating` on serializer `BookSerializer`.
The serializer field might be named incorrectly and not match any attribute or key on the `Book` instance.
Original exception text was: 'Book' object has no attribute 'reviews'.
WARNING:django.request:Bad Request: /api/v1/books/
INFO:django.utils.autoreload:/home/work/learning/tasks/book_app2/books/serializers/book_serializer.py changed, reloading.
ERROR:books.helpers.logging_helper:BookView get :: exception::  Got AttributeError when attempting to get a value for field `average_rating` on serializer `BookSerializer`.
The serializer field might be named incorrectly and not match any attribute or key on the `Book` instance.
Original exception text was: 'Book' object has no attribute 'reviews'.
WARNING:django.request:Bad Request: /api/v1/books/
INFO:django.utils.autoreload:/home/work/learning/tasks/book_app2/books/serializers/book_serializer.py changed, reloading.
ERROR:books.helpers.logging_helper:BookView get :: exception::  'Book' object has no attribute 'reviews'
WARNING:django.request:Bad Request: /api/v1/books/
INFO:django.utils.autoreload:/home/work/learning/tasks/book_app2/books/models/review.py changed, reloading.
ERROR:books.helpers.logging_helper:BookDetailView get :: exception :: ['“1” is not a valid UUID.']
WARNING:django.request:Bad Request: /api/v1/books/1/
ERROR:books.helpers.logging_helper:BookDetailView get :: exception :: ['“1” is not a valid UUID.']
WARNING:django.request:Bad Request: /api/v1/books/1/
INFO:django.utils.autoreload:/home/work/learning/tasks/book_app2/project/settings.py changed, reloading.
INFO:django.utils.autoreload:/home/work/learning/tasks/book_app2/project/settings.py changed, reloading.
INFO:django.utils.autoreload:/home/work/learning/tasks/book_app2/project/settings.py changed, reloading.
INFO:django.utils.autoreload:/home/work/learning/tasks/book_app2/project/settings.py changed, reloading.
INFO:django.utils.autoreload:/home/work/learning/tasks/book_app2/books/services/book_service.py changed, reloading.
INFO:django.utils.autoreload:/home/work/learning/tasks/book_app2/books/services/book_service.py changed, reloading.
INFO:django.utils.autoreload:/home/work/learning/tasks/book_app2/books/services/book_service.py changed, reloading.
INFO:django.utils.autoreload:/home/work/learning/tasks/book_app2/books/services/book_service.py changed, reloading.
INFO:django.utils.autoreload:/home/work/learning/tasks/book_app2/books/services/book_service.py changed, reloading.
INFO:django.utils.autoreload:/home/work/learning/tasks/book_app2/books/services/book_service.py changed, reloading.
INFO:django.utils.autoreload:/home/work/learning/tasks/book_app2/books/services/book_service.py changed, reloading.
INFO:django.utils.autoreload:/home/work/learning/tasks/book_app2/books/services/book_service.py changed, reloading.
INFO:django.utils.autoreload:/home/work/learning/tasks/book_app2/books/services/book_service.py changed, reloading.
INFO:django.utils.autoreload:/home/work/learning/tasks/book_app2/books/services/book_service.py changed, reloading.
INFO:django.utils.autoreload:/home/work/learning/tasks/book_app2/books/views/book_api.py changed, reloading.
INFO:django.utils.autoreload:/home/work/learning/tasks/book_app2/books/services/book_service.py changed, reloading.
INFO:django.utils.autoreload:/home/work/learning/tasks/book_app2/books/services/book_service.py changed, reloading.
INFO:django.utils.autoreload:/home/work/learning/tasks/book_app2/books/services/book_service.py changed, reloading.
INFO:django.utils.autoreload:/home/work/learning/tasks/book_app2/books/services/book_service.py changed, reloading.
ERROR:books.helpers.logging_helper:BookView get :: exception::  'ReturnList' object has no attribute 'data'
WARNING:django.request:Bad Request: /api/v1/books/
INFO:django.utils.autoreload:/home/work/learning/tasks/book_app2/books/services/book_service.py changed, reloading.
ERROR:django.request:Internal Server Error: /api/v1/books/
Traceback (most recent call last):
  File "/home/work/learning/tasks/book_app2/.venv/lib/python3.12/site-packages/django/core/handlers/exception.py", line 55, in inner
    response = get_response(request)
               ^^^^^^^^^^^^^^^^^^^^^
  File "/home/work/learning/tasks/book_app2/.venv/lib/python3.12/site-packages/django/core/handlers/base.py", line 220, in _get_response
    response = response.render()
               ^^^^^^^^^^^^^^^^^
  File "/home/work/learning/tasks/book_app2/.venv/lib/python3.12/site-packages/django/template/response.py", line 114, in render
    self.content = self.rendered_content
                   ^^^^^^^^^^^^^^^^^^^^^
  File "/home/work/learning/tasks/book_app2/.venv/lib/python3.12/site-packages/rest_framework/response.py", line 74, in rendered_content
    ret = renderer.render(self.data, accepted_media_type, context)
          ^^^^^^^^^^^^^^^^^^^^^^^^^^^^^^^^^^^^^^^^^^^^^^^^^^^^^^^^
  File "/home/work/learning/tasks/book_app2/.venv/lib/python3.12/site-packages/rest_framework/renderers.py", line 99, in render
    ret = json.dumps(
          ^^^^^^^^^^^
  File "/home/work/learning/tasks/book_app2/.venv/lib/python3.12/site-packages/rest_framework/utils/json.py", line 25, in dumps
    return json.dumps(*args, **kwargs)
           ^^^^^^^^^^^^^^^^^^^^^^^^^^^
  File "/usr/lib/python3.12/json/__init__.py", line 238, in dumps
    **kw).encode(obj)
          ^^^^^^^^^^^
  File "/usr/lib/python3.12/json/encoder.py", line 200, in encode
    chunks = self.iterencode(o, _one_shot=True)
             ^^^^^^^^^^^^^^^^^^^^^^^^^^^^^^^^^^
  File "/usr/lib/python3.12/json/encoder.py", line 258, in iterencode
    return _iterencode(o, 0)
           ^^^^^^^^^^^^^^^^^
  File "/home/work/learning/tasks/book_app2/.venv/lib/python3.12/site-packages/rest_framework/utils/encoders.py", line 67, in default
    return super().default(obj)
           ^^^^^^^^^^^^^^^^^^^^
  File "/usr/lib/python3.12/json/encoder.py", line 180, in default
    raise TypeError(f'Object of type {o.__class__.__name__} '
TypeError: Object of type Response is not JSON serializable
INFO:django.utils.autoreload:/home/work/learning/tasks/book_app2/books/views/book_api.py changed, reloading.
ERROR:django.request:Internal Server Error: /api/v1/books/
Traceback (most recent call last):
  File "/home/work/learning/tasks/book_app2/.venv/lib/python3.12/site-packages/django/core/handlers/exception.py", line 55, in inner
    response = get_response(request)
               ^^^^^^^^^^^^^^^^^^^^^
  File "/home/work/learning/tasks/book_app2/.venv/lib/python3.12/site-packages/django/core/handlers/base.py", line 220, in _get_response
    response = response.render()
               ^^^^^^^^^^^^^^^^^
  File "/home/work/learning/tasks/book_app2/.venv/lib/python3.12/site-packages/django/template/response.py", line 114, in render
    self.content = self.rendered_content
                   ^^^^^^^^^^^^^^^^^^^^^
  File "/home/work/learning/tasks/book_app2/.venv/lib/python3.12/site-packages/rest_framework/response.py", line 74, in rendered_content
    ret = renderer.render(self.data, accepted_media_type, context)
          ^^^^^^^^^^^^^^^^^^^^^^^^^^^^^^^^^^^^^^^^^^^^^^^^^^^^^^^^
  File "/home/work/learning/tasks/book_app2/.venv/lib/python3.12/site-packages/rest_framework/renderers.py", line 99, in render
    ret = json.dumps(
          ^^^^^^^^^^^
  File "/home/work/learning/tasks/book_app2/.venv/lib/python3.12/site-packages/rest_framework/utils/json.py", line 25, in dumps
    return json.dumps(*args, **kwargs)
           ^^^^^^^^^^^^^^^^^^^^^^^^^^^
  File "/usr/lib/python3.12/json/__init__.py", line 238, in dumps
    **kw).encode(obj)
          ^^^^^^^^^^^
  File "/usr/lib/python3.12/json/encoder.py", line 200, in encode
    chunks = self.iterencode(o, _one_shot=True)
             ^^^^^^^^^^^^^^^^^^^^^^^^^^^^^^^^^^
  File "/usr/lib/python3.12/json/encoder.py", line 258, in iterencode
    return _iterencode(o, 0)
           ^^^^^^^^^^^^^^^^^
  File "/home/work/learning/tasks/book_app2/.venv/lib/python3.12/site-packages/rest_framework/utils/encoders.py", line 67, in default
    return super().default(obj)
           ^^^^^^^^^^^^^^^^^^^^
  File "/usr/lib/python3.12/json/encoder.py", line 180, in default
    raise TypeError(f'Object of type {o.__class__.__name__} '
TypeError: Object of type Response is not JSON serializable
INFO:django.utils.autoreload:/home/work/learning/tasks/book_app2/books/views/book_api.py changed, reloading.
INFO:django.utils.autoreload:/home/work/learning/tasks/book_app2/books/views/book_api.py changed, reloading.
INFO:django.utils.autoreload:/home/work/learning/tasks/book_app2/books/services/book_service.py changed, reloading.
INFO:django.utils.autoreload:/home/work/learning/tasks/book_app2/books/services/book_service.py changed, reloading.
INFO:django.utils.autoreload:/home/work/learning/tasks/book_app2/books/views/book_api.py changed, reloading.
INFO:django.utils.autoreload:/home/work/learning/tasks/book_app2/books/views/book_api.py changed, reloading.
INFO:django.utils.autoreload:/home/work/learning/tasks/book_app2/books/views/book_api.py changed, reloading.
INFO:django.utils.autoreload:/home/work/learning/tasks/book_app2/books/views/book_api.py changed, reloading.
INFO:django.utils.autoreload:/home/work/learning/tasks/book_app2/books/views/book_api.py changed, reloading.
INFO:django.utils.autoreload:/home/work/learning/tasks/book_app2/books/views/book_api.py changed, reloading.
ERROR:books.helpers.logging_helper:BookView get :: exception::  Invalid page.
WARNING:django.request:Bad Request: /api/v1/books/
ERROR:books.helpers.logging_helper:BookView get :: exception::  Invalid page.
WARNING:django.request:Bad Request: /api/v1/books/
INFO:django.utils.autoreload:/home/work/learning/tasks/book_app2/books/views/book_api.py changed, reloading.
INFO:django.utils.autoreload:/home/work/learning/tasks/book_app2/books/views/book_api.py changed, reloading.
INFO:django.utils.autoreload:/home/work/learning/tasks/book_app2/books/services/book_service.py changed, reloading.
INFO:django.utils.autoreload:/home/work/learning/tasks/book_app2/books/services/book_service.py changed, reloading.
INFO:django.utils.autoreload:/home/work/learning/tasks/book_app2/books/services/book_service.py changed, reloading.
INFO:django.utils.autoreload:/home/work/learning/tasks/book_app2/books/services/book_service.py changed, reloading.
INFO:django.utils.autoreload:/home/work/learning/tasks/book_app2/books/services/book_service.py changed, reloading.
INFO:django.utils.autoreload:/home/work/learning/tasks/book_app2/books/services/book_service.py changed, reloading.
INFO:django.utils.autoreload:/home/work/learning/tasks/book_app2/books/services/book_service.py changed, reloading.
INFO:django.utils.autoreload:/home/work/learning/tasks/book_app2/books/services/book_service.py changed, reloading.
INFO:django.utils.autoreload:/home/work/learning/tasks/book_app2/books/services/book_service.py changed, reloading.
INFO:django.utils.autoreload:/home/work/learning/tasks/book_app2/books/services/book_service.py changed, reloading.
INFO:django.utils.autoreload:/home/work/learning/tasks/book_app2/books/services/book_service.py changed, reloading.
INFO:django.utils.autoreload:/home/work/learning/tasks/book_app2/books/services/book_service.py changed, reloading.
